[2024-05-15T00:44:49.345+0000] {processor.py:161} INFO - Started process (PID=42) to work on /opt/airflow/dags/dag_main.py
[2024-05-15T00:44:49.347+0000] {processor.py:830} INFO - Processing file /opt/airflow/dags/dag_main.py for tasks to queue
[2024-05-15T00:44:49.351+0000] {logging_mixin.py:188} INFO - [2024-05-15T00:44:49.350+0000] {dagbag.py:540} INFO - Filling up the DagBag from /opt/airflow/dags/dag_main.py
[2024-05-15T00:44:49.748+0000] {logging_mixin.py:188} INFO - [2024-05-15T00:44:49.744+0000] {dagbag.py:350} ERROR - Failed to import: /opt/airflow/dags/dag_main.py
Traceback (most recent call last):
  File "/home/airflow/.local/lib/python3.8/site-packages/airflow/models/dagbag.py", line 346, in parse
    loader.exec_module(new_module)
  File "<frozen importlib._bootstrap_external>", line 843, in exec_module
  File "<frozen importlib._bootstrap>", line 219, in _call_with_frames_removed
  File "/opt/airflow/dags/dag_main.py", line 6, in <module>
    from dags.functions.class_data_validation import ValidateInputtedData
ModuleNotFoundError: No module named 'dags'
[2024-05-15T00:44:49.750+0000] {processor.py:842} WARNING - No viable dags retrieved from /opt/airflow/dags/dag_main.py
[2024-05-15T00:44:49.783+0000] {processor.py:183} INFO - Processing /opt/airflow/dags/dag_main.py took 0.441 seconds
[2024-05-15T00:45:20.147+0000] {processor.py:161} INFO - Started process (PID=51) to work on /opt/airflow/dags/dag_main.py
[2024-05-15T00:45:20.150+0000] {processor.py:830} INFO - Processing file /opt/airflow/dags/dag_main.py for tasks to queue
[2024-05-15T00:45:20.166+0000] {logging_mixin.py:188} INFO - [2024-05-15T00:45:20.163+0000] {dagbag.py:540} INFO - Filling up the DagBag from /opt/airflow/dags/dag_main.py
[2024-05-15T00:45:20.359+0000] {logging_mixin.py:188} INFO - [2024-05-15T00:45:20.354+0000] {dagbag.py:350} ERROR - Failed to import: /opt/airflow/dags/dag_main.py
Traceback (most recent call last):
  File "/home/airflow/.local/lib/python3.8/site-packages/airflow/models/dagbag.py", line 346, in parse
    loader.exec_module(new_module)
  File "<frozen importlib._bootstrap_external>", line 843, in exec_module
  File "<frozen importlib._bootstrap>", line 219, in _call_with_frames_removed
  File "/opt/airflow/dags/dag_main.py", line 6, in <module>
    from dags.functions.class_data_validation import ValidateInputtedData
ModuleNotFoundError: No module named 'dags'
[2024-05-15T00:45:20.361+0000] {processor.py:842} WARNING - No viable dags retrieved from /opt/airflow/dags/dag_main.py
[2024-05-15T00:45:20.402+0000] {processor.py:183} INFO - Processing /opt/airflow/dags/dag_main.py took 0.274 seconds
[2024-05-15T00:45:50.640+0000] {processor.py:161} INFO - Started process (PID=60) to work on /opt/airflow/dags/dag_main.py
[2024-05-15T00:45:50.641+0000] {processor.py:830} INFO - Processing file /opt/airflow/dags/dag_main.py for tasks to queue
[2024-05-15T00:45:50.643+0000] {logging_mixin.py:188} INFO - [2024-05-15T00:45:50.643+0000] {dagbag.py:540} INFO - Filling up the DagBag from /opt/airflow/dags/dag_main.py
[2024-05-15T00:45:50.746+0000] {logging_mixin.py:188} INFO - [2024-05-15T00:45:50.743+0000] {dagbag.py:350} ERROR - Failed to import: /opt/airflow/dags/dag_main.py
Traceback (most recent call last):
  File "/home/airflow/.local/lib/python3.8/site-packages/airflow/models/dagbag.py", line 346, in parse
    loader.exec_module(new_module)
  File "<frozen importlib._bootstrap_external>", line 843, in exec_module
  File "<frozen importlib._bootstrap>", line 219, in _call_with_frames_removed
  File "/opt/airflow/dags/dag_main.py", line 6, in <module>
    from dags.functions.class_data_validation import ValidateInputtedData
ModuleNotFoundError: No module named 'dags'
[2024-05-15T00:45:50.747+0000] {processor.py:842} WARNING - No viable dags retrieved from /opt/airflow/dags/dag_main.py
[2024-05-15T00:45:50.782+0000] {processor.py:183} INFO - Processing /opt/airflow/dags/dag_main.py took 0.147 seconds
[2024-05-15T00:46:21.050+0000] {processor.py:161} INFO - Started process (PID=69) to work on /opt/airflow/dags/dag_main.py
[2024-05-15T00:46:21.052+0000] {processor.py:830} INFO - Processing file /opt/airflow/dags/dag_main.py for tasks to queue
[2024-05-15T00:46:21.053+0000] {logging_mixin.py:188} INFO - [2024-05-15T00:46:21.053+0000] {dagbag.py:540} INFO - Filling up the DagBag from /opt/airflow/dags/dag_main.py
[2024-05-15T00:46:21.124+0000] {logging_mixin.py:188} INFO - [2024-05-15T00:46:21.121+0000] {dagbag.py:350} ERROR - Failed to import: /opt/airflow/dags/dag_main.py
Traceback (most recent call last):
  File "/home/airflow/.local/lib/python3.8/site-packages/airflow/models/dagbag.py", line 346, in parse
    loader.exec_module(new_module)
  File "<frozen importlib._bootstrap_external>", line 843, in exec_module
  File "<frozen importlib._bootstrap>", line 219, in _call_with_frames_removed
  File "/opt/airflow/dags/dag_main.py", line 6, in <module>
    from dags.functions.class_data_validation import ValidateInputtedData
ModuleNotFoundError: No module named 'dags'
[2024-05-15T00:46:21.125+0000] {processor.py:842} WARNING - No viable dags retrieved from /opt/airflow/dags/dag_main.py
[2024-05-15T00:46:21.146+0000] {processor.py:183} INFO - Processing /opt/airflow/dags/dag_main.py took 0.098 seconds
[2024-05-15T00:46:51.389+0000] {processor.py:161} INFO - Started process (PID=78) to work on /opt/airflow/dags/dag_main.py
[2024-05-15T00:46:51.390+0000] {processor.py:830} INFO - Processing file /opt/airflow/dags/dag_main.py for tasks to queue
[2024-05-15T00:46:51.392+0000] {logging_mixin.py:188} INFO - [2024-05-15T00:46:51.392+0000] {dagbag.py:540} INFO - Filling up the DagBag from /opt/airflow/dags/dag_main.py
[2024-05-15T00:46:51.461+0000] {logging_mixin.py:188} INFO - [2024-05-15T00:46:51.458+0000] {dagbag.py:350} ERROR - Failed to import: /opt/airflow/dags/dag_main.py
Traceback (most recent call last):
  File "/home/airflow/.local/lib/python3.8/site-packages/airflow/models/dagbag.py", line 346, in parse
    loader.exec_module(new_module)
  File "<frozen importlib._bootstrap_external>", line 843, in exec_module
  File "<frozen importlib._bootstrap>", line 219, in _call_with_frames_removed
  File "/opt/airflow/dags/dag_main.py", line 6, in <module>
    from dags.functions.class_data_validation import ValidateInputtedData
ModuleNotFoundError: No module named 'dags'
[2024-05-15T00:46:51.462+0000] {processor.py:842} WARNING - No viable dags retrieved from /opt/airflow/dags/dag_main.py
[2024-05-15T00:46:51.481+0000] {processor.py:183} INFO - Processing /opt/airflow/dags/dag_main.py took 0.094 seconds
[2024-05-15T00:47:21.706+0000] {processor.py:161} INFO - Started process (PID=87) to work on /opt/airflow/dags/dag_main.py
[2024-05-15T00:47:21.707+0000] {processor.py:830} INFO - Processing file /opt/airflow/dags/dag_main.py for tasks to queue
[2024-05-15T00:47:21.709+0000] {logging_mixin.py:188} INFO - [2024-05-15T00:47:21.709+0000] {dagbag.py:540} INFO - Filling up the DagBag from /opt/airflow/dags/dag_main.py
[2024-05-15T00:47:21.783+0000] {logging_mixin.py:188} INFO - [2024-05-15T00:47:21.780+0000] {dagbag.py:350} ERROR - Failed to import: /opt/airflow/dags/dag_main.py
Traceback (most recent call last):
  File "/home/airflow/.local/lib/python3.8/site-packages/airflow/models/dagbag.py", line 346, in parse
    loader.exec_module(new_module)
  File "<frozen importlib._bootstrap_external>", line 843, in exec_module
  File "<frozen importlib._bootstrap>", line 219, in _call_with_frames_removed
  File "/opt/airflow/dags/dag_main.py", line 6, in <module>
    from dags.functions.class_data_validation import ValidateInputtedData
ModuleNotFoundError: No module named 'dags'
[2024-05-15T00:47:21.784+0000] {processor.py:842} WARNING - No viable dags retrieved from /opt/airflow/dags/dag_main.py
[2024-05-15T00:47:21.802+0000] {processor.py:183} INFO - Processing /opt/airflow/dags/dag_main.py took 0.100 seconds
[2024-05-15T00:47:29.893+0000] {processor.py:161} INFO - Started process (PID=91) to work on /opt/airflow/dags/dag_main.py
[2024-05-15T00:47:29.894+0000] {processor.py:830} INFO - Processing file /opt/airflow/dags/dag_main.py for tasks to queue
[2024-05-15T00:47:29.896+0000] {logging_mixin.py:188} INFO - [2024-05-15T00:47:29.895+0000] {dagbag.py:540} INFO - Filling up the DagBag from /opt/airflow/dags/dag_main.py
[2024-05-15T00:47:29.983+0000] {logging_mixin.py:188} INFO - [2024-05-15T00:47:29.979+0000] {dagbag.py:350} ERROR - Failed to import: /opt/airflow/dags/dag_main.py
Traceback (most recent call last):
  File "/home/airflow/.local/lib/python3.8/site-packages/airflow/models/dagbag.py", line 346, in parse
    loader.exec_module(new_module)
  File "<frozen importlib._bootstrap_external>", line 843, in exec_module
  File "<frozen importlib._bootstrap>", line 219, in _call_with_frames_removed
  File "/opt/airflow/dags/dag_main.py", line 6, in <module>
    from functions.class_data_validation import ValidateInputtedData
  File "/opt/airflow/dags/functions/class_data_validation.py", line 5, in <module>
    from function_data_validation import *
ModuleNotFoundError: No module named 'function_data_validation'
[2024-05-15T00:47:29.985+0000] {processor.py:842} WARNING - No viable dags retrieved from /opt/airflow/dags/dag_main.py
[2024-05-15T00:47:30.004+0000] {processor.py:183} INFO - Processing /opt/airflow/dags/dag_main.py took 0.114 seconds
[2024-05-15T00:48:00.243+0000] {processor.py:161} INFO - Started process (PID=100) to work on /opt/airflow/dags/dag_main.py
[2024-05-15T00:48:00.244+0000] {processor.py:830} INFO - Processing file /opt/airflow/dags/dag_main.py for tasks to queue
[2024-05-15T00:48:00.246+0000] {logging_mixin.py:188} INFO - [2024-05-15T00:48:00.246+0000] {dagbag.py:540} INFO - Filling up the DagBag from /opt/airflow/dags/dag_main.py
[2024-05-15T00:48:00.323+0000] {logging_mixin.py:188} INFO - [2024-05-15T00:48:00.318+0000] {dagbag.py:350} ERROR - Failed to import: /opt/airflow/dags/dag_main.py
Traceback (most recent call last):
  File "/home/airflow/.local/lib/python3.8/site-packages/airflow/models/dagbag.py", line 346, in parse
    loader.exec_module(new_module)
  File "<frozen importlib._bootstrap_external>", line 843, in exec_module
  File "<frozen importlib._bootstrap>", line 219, in _call_with_frames_removed
  File "/opt/airflow/dags/dag_main.py", line 6, in <module>
    from functions.class_data_validation import ValidateInputtedData
  File "/opt/airflow/dags/functions/class_data_validation.py", line 5, in <module>
    from function_data_validation import *
ModuleNotFoundError: No module named 'function_data_validation'
[2024-05-15T00:48:00.324+0000] {processor.py:842} WARNING - No viable dags retrieved from /opt/airflow/dags/dag_main.py
[2024-05-15T00:48:00.339+0000] {processor.py:183} INFO - Processing /opt/airflow/dags/dag_main.py took 0.098 seconds
[2024-05-15T00:48:30.586+0000] {processor.py:161} INFO - Started process (PID=109) to work on /opt/airflow/dags/dag_main.py
[2024-05-15T00:48:30.587+0000] {processor.py:830} INFO - Processing file /opt/airflow/dags/dag_main.py for tasks to queue
[2024-05-15T00:48:30.589+0000] {logging_mixin.py:188} INFO - [2024-05-15T00:48:30.589+0000] {dagbag.py:540} INFO - Filling up the DagBag from /opt/airflow/dags/dag_main.py
[2024-05-15T00:48:30.660+0000] {logging_mixin.py:188} INFO - [2024-05-15T00:48:30.655+0000] {dagbag.py:350} ERROR - Failed to import: /opt/airflow/dags/dag_main.py
Traceback (most recent call last):
  File "/home/airflow/.local/lib/python3.8/site-packages/airflow/models/dagbag.py", line 346, in parse
    loader.exec_module(new_module)
  File "<frozen importlib._bootstrap_external>", line 843, in exec_module
  File "<frozen importlib._bootstrap>", line 219, in _call_with_frames_removed
  File "/opt/airflow/dags/dag_main.py", line 6, in <module>
    from functions.class_data_validation import ValidateInputtedData
  File "/opt/airflow/dags/functions/class_data_validation.py", line 5, in <module>
    from function_data_validation import *
ModuleNotFoundError: No module named 'function_data_validation'
[2024-05-15T00:48:30.662+0000] {processor.py:842} WARNING - No viable dags retrieved from /opt/airflow/dags/dag_main.py
[2024-05-15T00:48:30.678+0000] {processor.py:183} INFO - Processing /opt/airflow/dags/dag_main.py took 0.094 seconds
[2024-05-15T00:49:00.937+0000] {processor.py:161} INFO - Started process (PID=118) to work on /opt/airflow/dags/dag_main.py
[2024-05-15T00:49:00.938+0000] {processor.py:830} INFO - Processing file /opt/airflow/dags/dag_main.py for tasks to queue
[2024-05-15T00:49:00.940+0000] {logging_mixin.py:188} INFO - [2024-05-15T00:49:00.940+0000] {dagbag.py:540} INFO - Filling up the DagBag from /opt/airflow/dags/dag_main.py
[2024-05-15T00:49:02.623+0000] {logging_mixin.py:188} INFO - [2024-05-15T00:49:02.613+0000] {dagbag.py:350} ERROR - Failed to import: /opt/airflow/dags/dag_main.py
Traceback (most recent call last):
  File "/home/airflow/.local/lib/python3.8/site-packages/airflow/models/dagbag.py", line 346, in parse
    loader.exec_module(new_module)
  File "<frozen importlib._bootstrap_external>", line 843, in exec_module
  File "<frozen importlib._bootstrap>", line 219, in _call_with_frames_removed
  File "/opt/airflow/dags/dag_main.py", line 6, in <module>
    from functions.class_data_validation import ValidateInputtedData
  File "/opt/airflow/dags/functions/class_data_validation.py", line 5, in <module>
    from functions.function_data_validation import *
  File "/opt/airflow/dags/functions/function_data_validation.py", line 2, in <module>
    import great_expectations as ge
ModuleNotFoundError: No module named 'great_expectations'
[2024-05-15T00:49:02.625+0000] {processor.py:842} WARNING - No viable dags retrieved from /opt/airflow/dags/dag_main.py
[2024-05-15T00:49:02.643+0000] {processor.py:183} INFO - Processing /opt/airflow/dags/dag_main.py took 1.709 seconds
[2024-05-15T00:49:33.448+0000] {processor.py:161} INFO - Started process (PID=128) to work on /opt/airflow/dags/dag_main.py
[2024-05-15T00:49:33.449+0000] {processor.py:830} INFO - Processing file /opt/airflow/dags/dag_main.py for tasks to queue
[2024-05-15T00:49:33.451+0000] {logging_mixin.py:188} INFO - [2024-05-15T00:49:33.450+0000] {dagbag.py:540} INFO - Filling up the DagBag from /opt/airflow/dags/dag_main.py
[2024-05-15T00:49:33.898+0000] {logging_mixin.py:188} INFO - [2024-05-15T00:49:33.889+0000] {dagbag.py:350} ERROR - Failed to import: /opt/airflow/dags/dag_main.py
Traceback (most recent call last):
  File "/home/airflow/.local/lib/python3.8/site-packages/airflow/models/dagbag.py", line 346, in parse
    loader.exec_module(new_module)
  File "<frozen importlib._bootstrap_external>", line 843, in exec_module
  File "<frozen importlib._bootstrap>", line 219, in _call_with_frames_removed
  File "/opt/airflow/dags/dag_main.py", line 6, in <module>
    from functions.class_data_validation import ValidateInputtedData
  File "/opt/airflow/dags/functions/class_data_validation.py", line 5, in <module>
    from functions.function_data_validation import *
  File "/opt/airflow/dags/functions/function_data_validation.py", line 2, in <module>
    import great_expectations as ge
ModuleNotFoundError: No module named 'great_expectations'
[2024-05-15T00:49:33.900+0000] {processor.py:842} WARNING - No viable dags retrieved from /opt/airflow/dags/dag_main.py
[2024-05-15T00:49:33.915+0000] {processor.py:183} INFO - Processing /opt/airflow/dags/dag_main.py took 0.470 seconds
[2024-05-15T00:50:04.016+0000] {processor.py:161} INFO - Started process (PID=138) to work on /opt/airflow/dags/dag_main.py
[2024-05-15T00:50:04.017+0000] {processor.py:830} INFO - Processing file /opt/airflow/dags/dag_main.py for tasks to queue
[2024-05-15T00:50:04.018+0000] {logging_mixin.py:188} INFO - [2024-05-15T00:50:04.018+0000] {dagbag.py:540} INFO - Filling up the DagBag from /opt/airflow/dags/dag_main.py
[2024-05-15T00:50:04.422+0000] {logging_mixin.py:188} INFO - [2024-05-15T00:50:04.414+0000] {dagbag.py:350} ERROR - Failed to import: /opt/airflow/dags/dag_main.py
Traceback (most recent call last):
  File "/home/airflow/.local/lib/python3.8/site-packages/airflow/models/dagbag.py", line 346, in parse
    loader.exec_module(new_module)
  File "<frozen importlib._bootstrap_external>", line 843, in exec_module
  File "<frozen importlib._bootstrap>", line 219, in _call_with_frames_removed
  File "/opt/airflow/dags/dag_main.py", line 6, in <module>
    from functions.class_data_validation import ValidateInputtedData
  File "/opt/airflow/dags/functions/class_data_validation.py", line 5, in <module>
    from functions.function_data_validation import *
  File "/opt/airflow/dags/functions/function_data_validation.py", line 2, in <module>
    import great_expectations as ge
ModuleNotFoundError: No module named 'great_expectations'
[2024-05-15T00:50:04.424+0000] {processor.py:842} WARNING - No viable dags retrieved from /opt/airflow/dags/dag_main.py
[2024-05-15T00:50:04.443+0000] {processor.py:183} INFO - Processing /opt/airflow/dags/dag_main.py took 0.430 seconds
[2024-05-15T00:50:35.317+0000] {processor.py:161} INFO - Started process (PID=148) to work on /opt/airflow/dags/dag_main.py
[2024-05-15T00:50:35.318+0000] {processor.py:830} INFO - Processing file /opt/airflow/dags/dag_main.py for tasks to queue
[2024-05-15T00:50:35.320+0000] {logging_mixin.py:188} INFO - [2024-05-15T00:50:35.320+0000] {dagbag.py:540} INFO - Filling up the DagBag from /opt/airflow/dags/dag_main.py
[2024-05-15T00:50:35.405+0000] {logging_mixin.py:188} INFO - [2024-05-15T00:50:35.401+0000] {dagbag.py:350} ERROR - Failed to import: /opt/airflow/dags/dag_main.py
Traceback (most recent call last):
  File "/home/airflow/.local/lib/python3.8/site-packages/airflow/models/dagbag.py", line 346, in parse
    loader.exec_module(new_module)
  File "<frozen importlib._bootstrap_external>", line 843, in exec_module
  File "<frozen importlib._bootstrap>", line 219, in _call_with_frames_removed
  File "/opt/airflow/dags/dag_main.py", line 6, in <module>
    from functions.class_data_validation import ValidateInputtedData
  File "/opt/airflow/dags/functions/class_data_validation.py", line 5, in <module>
    from function_data_validation import get_data, validate_data
ModuleNotFoundError: No module named 'function_data_validation'
[2024-05-15T00:50:35.407+0000] {processor.py:842} WARNING - No viable dags retrieved from /opt/airflow/dags/dag_main.py
[2024-05-15T00:50:35.424+0000] {processor.py:183} INFO - Processing /opt/airflow/dags/dag_main.py took 0.109 seconds
[2024-05-15T00:51:05.730+0000] {processor.py:161} INFO - Started process (PID=157) to work on /opt/airflow/dags/dag_main.py
[2024-05-15T00:51:05.731+0000] {processor.py:830} INFO - Processing file /opt/airflow/dags/dag_main.py for tasks to queue
[2024-05-15T00:51:05.733+0000] {logging_mixin.py:188} INFO - [2024-05-15T00:51:05.733+0000] {dagbag.py:540} INFO - Filling up the DagBag from /opt/airflow/dags/dag_main.py
[2024-05-15T00:51:05.814+0000] {logging_mixin.py:188} INFO - [2024-05-15T00:51:05.809+0000] {dagbag.py:350} ERROR - Failed to import: /opt/airflow/dags/dag_main.py
Traceback (most recent call last):
  File "/home/airflow/.local/lib/python3.8/site-packages/airflow/models/dagbag.py", line 346, in parse
    loader.exec_module(new_module)
  File "<frozen importlib._bootstrap_external>", line 843, in exec_module
  File "<frozen importlib._bootstrap>", line 219, in _call_with_frames_removed
  File "/opt/airflow/dags/dag_main.py", line 6, in <module>
    from functions.class_data_validation import ValidateInputtedData
  File "/opt/airflow/dags/functions/class_data_validation.py", line 5, in <module>
    from function_data_validation import get_data, validate_data
ModuleNotFoundError: No module named 'function_data_validation'
[2024-05-15T00:51:05.816+0000] {processor.py:842} WARNING - No viable dags retrieved from /opt/airflow/dags/dag_main.py
[2024-05-15T00:51:05.840+0000] {processor.py:183} INFO - Processing /opt/airflow/dags/dag_main.py took 0.114 seconds
[2024-05-15T00:51:36.170+0000] {processor.py:161} INFO - Started process (PID=166) to work on /opt/airflow/dags/dag_main.py
[2024-05-15T00:51:36.171+0000] {processor.py:830} INFO - Processing file /opt/airflow/dags/dag_main.py for tasks to queue
[2024-05-15T00:51:36.172+0000] {logging_mixin.py:188} INFO - [2024-05-15T00:51:36.172+0000] {dagbag.py:540} INFO - Filling up the DagBag from /opt/airflow/dags/dag_main.py
[2024-05-15T00:51:36.247+0000] {logging_mixin.py:188} INFO - [2024-05-15T00:51:36.243+0000] {dagbag.py:350} ERROR - Failed to import: /opt/airflow/dags/dag_main.py
Traceback (most recent call last):
  File "/home/airflow/.local/lib/python3.8/site-packages/airflow/models/dagbag.py", line 346, in parse
    loader.exec_module(new_module)
  File "<frozen importlib._bootstrap_external>", line 843, in exec_module
  File "<frozen importlib._bootstrap>", line 219, in _call_with_frames_removed
  File "/opt/airflow/dags/dag_main.py", line 6, in <module>
    from functions.class_data_validation import ValidateInputtedData
  File "/opt/airflow/dags/functions/class_data_validation.py", line 5, in <module>
    from function_data_validation import get_data, validate_data
ModuleNotFoundError: No module named 'function_data_validation'
[2024-05-15T00:51:36.249+0000] {processor.py:842} WARNING - No viable dags retrieved from /opt/airflow/dags/dag_main.py
[2024-05-15T00:51:36.264+0000] {processor.py:183} INFO - Processing /opt/airflow/dags/dag_main.py took 0.097 seconds
[2024-05-15T00:52:06.538+0000] {processor.py:161} INFO - Started process (PID=175) to work on /opt/airflow/dags/dag_main.py
[2024-05-15T00:52:06.539+0000] {processor.py:830} INFO - Processing file /opt/airflow/dags/dag_main.py for tasks to queue
[2024-05-15T00:52:06.541+0000] {logging_mixin.py:188} INFO - [2024-05-15T00:52:06.540+0000] {dagbag.py:540} INFO - Filling up the DagBag from /opt/airflow/dags/dag_main.py
[2024-05-15T00:52:06.621+0000] {logging_mixin.py:188} INFO - [2024-05-15T00:52:06.617+0000] {dagbag.py:350} ERROR - Failed to import: /opt/airflow/dags/dag_main.py
Traceback (most recent call last):
  File "/home/airflow/.local/lib/python3.8/site-packages/airflow/models/dagbag.py", line 346, in parse
    loader.exec_module(new_module)
  File "<frozen importlib._bootstrap_external>", line 843, in exec_module
  File "<frozen importlib._bootstrap>", line 219, in _call_with_frames_removed
  File "/opt/airflow/dags/dag_main.py", line 6, in <module>
    from functions.class_data_validation import ValidateInputtedData
  File "/opt/airflow/dags/functions/class_data_validation.py", line 5, in <module>
    from function_data_validation import get_data, validate_data
ModuleNotFoundError: No module named 'function_data_validation'
[2024-05-15T00:52:06.622+0000] {processor.py:842} WARNING - No viable dags retrieved from /opt/airflow/dags/dag_main.py
[2024-05-15T00:52:06.637+0000] {processor.py:183} INFO - Processing /opt/airflow/dags/dag_main.py took 0.102 seconds
[2024-05-15T00:52:36.994+0000] {processor.py:161} INFO - Started process (PID=190) to work on /opt/airflow/dags/dag_main.py
[2024-05-15T00:52:36.995+0000] {processor.py:830} INFO - Processing file /opt/airflow/dags/dag_main.py for tasks to queue
[2024-05-15T00:52:36.996+0000] {logging_mixin.py:188} INFO - [2024-05-15T00:52:36.996+0000] {dagbag.py:540} INFO - Filling up the DagBag from /opt/airflow/dags/dag_main.py
[2024-05-15T00:52:37.072+0000] {logging_mixin.py:188} INFO - [2024-05-15T00:52:37.067+0000] {dagbag.py:350} ERROR - Failed to import: /opt/airflow/dags/dag_main.py
Traceback (most recent call last):
  File "/home/airflow/.local/lib/python3.8/site-packages/airflow/models/dagbag.py", line 346, in parse
    loader.exec_module(new_module)
  File "<frozen importlib._bootstrap_external>", line 843, in exec_module
  File "<frozen importlib._bootstrap>", line 219, in _call_with_frames_removed
  File "/opt/airflow/dags/dag_main.py", line 6, in <module>
    from functions.class_data_validation import ValidateInputtedData
  File "/opt/airflow/dags/functions/class_data_validation.py", line 5, in <module>
    from function_data_validation import get_data, validate_data
ModuleNotFoundError: No module named 'function_data_validation'
[2024-05-15T00:52:37.074+0000] {processor.py:842} WARNING - No viable dags retrieved from /opt/airflow/dags/dag_main.py
[2024-05-15T00:52:37.088+0000] {processor.py:183} INFO - Processing /opt/airflow/dags/dag_main.py took 0.098 seconds
[2024-05-15T00:53:07.426+0000] {processor.py:161} INFO - Started process (PID=199) to work on /opt/airflow/dags/dag_main.py
[2024-05-15T00:53:07.427+0000] {processor.py:830} INFO - Processing file /opt/airflow/dags/dag_main.py for tasks to queue
[2024-05-15T00:53:07.429+0000] {logging_mixin.py:188} INFO - [2024-05-15T00:53:07.428+0000] {dagbag.py:540} INFO - Filling up the DagBag from /opt/airflow/dags/dag_main.py
[2024-05-15T00:53:07.510+0000] {logging_mixin.py:188} INFO - [2024-05-15T00:53:07.505+0000] {dagbag.py:350} ERROR - Failed to import: /opt/airflow/dags/dag_main.py
Traceback (most recent call last):
  File "/home/airflow/.local/lib/python3.8/site-packages/airflow/models/dagbag.py", line 346, in parse
    loader.exec_module(new_module)
  File "<frozen importlib._bootstrap_external>", line 843, in exec_module
  File "<frozen importlib._bootstrap>", line 219, in _call_with_frames_removed
  File "/opt/airflow/dags/dag_main.py", line 6, in <module>
    from functions.class_data_validation import ValidateInputtedData
  File "/opt/airflow/dags/functions/class_data_validation.py", line 5, in <module>
    from function_data_validation import get_data, validate_data
ModuleNotFoundError: No module named 'function_data_validation'
[2024-05-15T00:53:07.513+0000] {processor.py:842} WARNING - No viable dags retrieved from /opt/airflow/dags/dag_main.py
[2024-05-15T00:53:07.529+0000] {processor.py:183} INFO - Processing /opt/airflow/dags/dag_main.py took 0.105 seconds
[2024-05-15T00:53:37.886+0000] {processor.py:161} INFO - Started process (PID=208) to work on /opt/airflow/dags/dag_main.py
[2024-05-15T00:53:37.887+0000] {processor.py:830} INFO - Processing file /opt/airflow/dags/dag_main.py for tasks to queue
[2024-05-15T00:53:37.889+0000] {logging_mixin.py:188} INFO - [2024-05-15T00:53:37.889+0000] {dagbag.py:540} INFO - Filling up the DagBag from /opt/airflow/dags/dag_main.py
[2024-05-15T00:53:37.977+0000] {logging_mixin.py:188} INFO - [2024-05-15T00:53:37.970+0000] {dagbag.py:350} ERROR - Failed to import: /opt/airflow/dags/dag_main.py
Traceback (most recent call last):
  File "/home/airflow/.local/lib/python3.8/site-packages/airflow/models/dagbag.py", line 346, in parse
    loader.exec_module(new_module)
  File "<frozen importlib._bootstrap_external>", line 843, in exec_module
  File "<frozen importlib._bootstrap>", line 219, in _call_with_frames_removed
  File "/opt/airflow/dags/dag_main.py", line 6, in <module>
    from functions.class_data_validation import ValidateInputtedData
  File "/opt/airflow/dags/functions/class_data_validation.py", line 5, in <module>
    from function_data_validation import get_data, validate_data
ModuleNotFoundError: No module named 'function_data_validation'
[2024-05-15T00:53:37.980+0000] {processor.py:842} WARNING - No viable dags retrieved from /opt/airflow/dags/dag_main.py
[2024-05-15T00:53:37.995+0000] {processor.py:183} INFO - Processing /opt/airflow/dags/dag_main.py took 0.112 seconds
[2024-05-15T00:54:08.292+0000] {processor.py:161} INFO - Started process (PID=217) to work on /opt/airflow/dags/dag_main.py
[2024-05-15T00:54:08.293+0000] {processor.py:830} INFO - Processing file /opt/airflow/dags/dag_main.py for tasks to queue
[2024-05-15T00:54:08.295+0000] {logging_mixin.py:188} INFO - [2024-05-15T00:54:08.295+0000] {dagbag.py:540} INFO - Filling up the DagBag from /opt/airflow/dags/dag_main.py
[2024-05-15T00:54:08.370+0000] {logging_mixin.py:188} INFO - [2024-05-15T00:54:08.366+0000] {dagbag.py:350} ERROR - Failed to import: /opt/airflow/dags/dag_main.py
Traceback (most recent call last):
  File "/home/airflow/.local/lib/python3.8/site-packages/airflow/models/dagbag.py", line 346, in parse
    loader.exec_module(new_module)
  File "<frozen importlib._bootstrap_external>", line 843, in exec_module
  File "<frozen importlib._bootstrap>", line 219, in _call_with_frames_removed
  File "/opt/airflow/dags/dag_main.py", line 6, in <module>
    from functions.class_data_validation import ValidateInputtedData
  File "/opt/airflow/dags/functions/class_data_validation.py", line 5, in <module>
    from function_data_validation import get_data, validate_data
ModuleNotFoundError: No module named 'function_data_validation'
[2024-05-15T00:54:08.372+0000] {processor.py:842} WARNING - No viable dags retrieved from /opt/airflow/dags/dag_main.py
[2024-05-15T00:54:08.387+0000] {processor.py:183} INFO - Processing /opt/airflow/dags/dag_main.py took 0.097 seconds
[2024-05-15T00:54:38.708+0000] {processor.py:161} INFO - Started process (PID=226) to work on /opt/airflow/dags/dag_main.py
[2024-05-15T00:54:38.709+0000] {processor.py:830} INFO - Processing file /opt/airflow/dags/dag_main.py for tasks to queue
[2024-05-15T00:54:38.711+0000] {logging_mixin.py:188} INFO - [2024-05-15T00:54:38.710+0000] {dagbag.py:540} INFO - Filling up the DagBag from /opt/airflow/dags/dag_main.py
[2024-05-15T00:54:38.785+0000] {logging_mixin.py:188} INFO - [2024-05-15T00:54:38.781+0000] {dagbag.py:350} ERROR - Failed to import: /opt/airflow/dags/dag_main.py
Traceback (most recent call last):
  File "/home/airflow/.local/lib/python3.8/site-packages/airflow/models/dagbag.py", line 346, in parse
    loader.exec_module(new_module)
  File "<frozen importlib._bootstrap_external>", line 843, in exec_module
  File "<frozen importlib._bootstrap>", line 219, in _call_with_frames_removed
  File "/opt/airflow/dags/dag_main.py", line 6, in <module>
    from functions.class_data_validation import ValidateInputtedData
  File "/opt/airflow/dags/functions/class_data_validation.py", line 5, in <module>
    from function_data_validation import get_data, validate_data
ModuleNotFoundError: No module named 'function_data_validation'
[2024-05-15T00:54:38.787+0000] {processor.py:842} WARNING - No viable dags retrieved from /opt/airflow/dags/dag_main.py
[2024-05-15T00:54:38.805+0000] {processor.py:183} INFO - Processing /opt/airflow/dags/dag_main.py took 0.100 seconds
[2024-05-15T00:55:09.191+0000] {processor.py:161} INFO - Started process (PID=235) to work on /opt/airflow/dags/dag_main.py
[2024-05-15T00:55:09.192+0000] {processor.py:830} INFO - Processing file /opt/airflow/dags/dag_main.py for tasks to queue
[2024-05-15T00:55:09.193+0000] {logging_mixin.py:188} INFO - [2024-05-15T00:55:09.193+0000] {dagbag.py:540} INFO - Filling up the DagBag from /opt/airflow/dags/dag_main.py
[2024-05-15T00:55:09.269+0000] {logging_mixin.py:188} INFO - [2024-05-15T00:55:09.264+0000] {dagbag.py:350} ERROR - Failed to import: /opt/airflow/dags/dag_main.py
Traceback (most recent call last):
  File "/home/airflow/.local/lib/python3.8/site-packages/airflow/models/dagbag.py", line 346, in parse
    loader.exec_module(new_module)
  File "<frozen importlib._bootstrap_external>", line 843, in exec_module
  File "<frozen importlib._bootstrap>", line 219, in _call_with_frames_removed
  File "/opt/airflow/dags/dag_main.py", line 6, in <module>
    from functions.class_data_validation import ValidateInputtedData
  File "/opt/airflow/dags/functions/class_data_validation.py", line 5, in <module>
    from function_data_validation import get_data, validate_data
ModuleNotFoundError: No module named 'function_data_validation'
[2024-05-15T00:55:09.271+0000] {processor.py:842} WARNING - No viable dags retrieved from /opt/airflow/dags/dag_main.py
[2024-05-15T00:55:09.289+0000] {processor.py:183} INFO - Processing /opt/airflow/dags/dag_main.py took 0.101 seconds
[2024-05-15T00:57:40.625+0000] {processor.py:161} INFO - Started process (PID=43) to work on /opt/airflow/dags/dag_main.py
[2024-05-15T00:57:40.626+0000] {processor.py:830} INFO - Processing file /opt/airflow/dags/dag_main.py for tasks to queue
[2024-05-15T00:57:40.629+0000] {logging_mixin.py:188} INFO - [2024-05-15T00:57:40.628+0000] {dagbag.py:540} INFO - Filling up the DagBag from /opt/airflow/dags/dag_main.py
[2024-05-15T00:57:40.977+0000] {logging_mixin.py:188} INFO - [2024-05-15T00:57:40.972+0000] {dagbag.py:350} ERROR - Failed to import: /opt/airflow/dags/dag_main.py
Traceback (most recent call last):
  File "/home/airflow/.local/lib/python3.8/site-packages/airflow/models/dagbag.py", line 346, in parse
    loader.exec_module(new_module)
  File "<frozen importlib._bootstrap_external>", line 843, in exec_module
  File "<frozen importlib._bootstrap>", line 219, in _call_with_frames_removed
  File "/opt/airflow/dags/dag_main.py", line 6, in <module>
    from functions.class_data_validation import ValidateInputtedData
  File "/opt/airflow/dags/functions/class_data_validation.py", line 5, in <module>
    from function_data_validation import get_data, validate_data
ModuleNotFoundError: No module named 'function_data_validation'
[2024-05-15T00:57:40.980+0000] {processor.py:842} WARNING - No viable dags retrieved from /opt/airflow/dags/dag_main.py
[2024-05-15T00:57:41.001+0000] {processor.py:183} INFO - Processing /opt/airflow/dags/dag_main.py took 0.380 seconds
[2024-05-15T00:58:59.985+0000] {processor.py:161} INFO - Started process (PID=43) to work on /opt/airflow/dags/dag_main.py
[2024-05-15T00:58:59.986+0000] {processor.py:830} INFO - Processing file /opt/airflow/dags/dag_main.py for tasks to queue
[2024-05-15T00:58:59.990+0000] {logging_mixin.py:188} INFO - [2024-05-15T00:58:59.989+0000] {dagbag.py:540} INFO - Filling up the DagBag from /opt/airflow/dags/dag_main.py
[2024-05-15T00:59:00.316+0000] {logging_mixin.py:188} INFO - [2024-05-15T00:59:00.309+0000] {dagbag.py:350} ERROR - Failed to import: /opt/airflow/dags/dag_main.py
Traceback (most recent call last):
  File "/home/airflow/.local/lib/python3.8/site-packages/airflow/models/dagbag.py", line 346, in parse
    loader.exec_module(new_module)
  File "<frozen importlib._bootstrap_external>", line 843, in exec_module
  File "<frozen importlib._bootstrap>", line 219, in _call_with_frames_removed
  File "/opt/airflow/dags/dag_main.py", line 6, in <module>
    from functions.class_data_validation import ValidateInputtedData
  File "/opt/airflow/dags/functions/class_data_validation.py", line 5, in <module>
    from function_data_validation import get_data, validate_data
ModuleNotFoundError: No module named 'function_data_validation'
[2024-05-15T00:59:00.318+0000] {processor.py:842} WARNING - No viable dags retrieved from /opt/airflow/dags/dag_main.py
[2024-05-15T00:59:00.344+0000] {processor.py:183} INFO - Processing /opt/airflow/dags/dag_main.py took 0.364 seconds
[2024-05-15T00:59:30.625+0000] {processor.py:161} INFO - Started process (PID=52) to work on /opt/airflow/dags/dag_main.py
[2024-05-15T00:59:30.626+0000] {processor.py:830} INFO - Processing file /opt/airflow/dags/dag_main.py for tasks to queue
[2024-05-15T00:59:30.628+0000] {logging_mixin.py:188} INFO - [2024-05-15T00:59:30.627+0000] {dagbag.py:540} INFO - Filling up the DagBag from /opt/airflow/dags/dag_main.py
[2024-05-15T00:59:30.701+0000] {logging_mixin.py:188} INFO - [2024-05-15T00:59:30.696+0000] {dagbag.py:350} ERROR - Failed to import: /opt/airflow/dags/dag_main.py
Traceback (most recent call last):
  File "/home/airflow/.local/lib/python3.8/site-packages/airflow/models/dagbag.py", line 346, in parse
    loader.exec_module(new_module)
  File "<frozen importlib._bootstrap_external>", line 843, in exec_module
  File "<frozen importlib._bootstrap>", line 219, in _call_with_frames_removed
  File "/opt/airflow/dags/dag_main.py", line 6, in <module>
    from functions.class_data_validation import ValidateInputtedData
  File "/opt/airflow/dags/functions/class_data_validation.py", line 5, in <module>
    from function_data_validation import get_data, validate_data
ModuleNotFoundError: No module named 'function_data_validation'
[2024-05-15T00:59:30.703+0000] {processor.py:842} WARNING - No viable dags retrieved from /opt/airflow/dags/dag_main.py
[2024-05-15T00:59:30.725+0000] {processor.py:183} INFO - Processing /opt/airflow/dags/dag_main.py took 0.103 seconds
[2024-05-15T01:00:01.023+0000] {processor.py:161} INFO - Started process (PID=61) to work on /opt/airflow/dags/dag_main.py
[2024-05-15T01:00:01.024+0000] {processor.py:830} INFO - Processing file /opt/airflow/dags/dag_main.py for tasks to queue
[2024-05-15T01:00:01.026+0000] {logging_mixin.py:188} INFO - [2024-05-15T01:00:01.025+0000] {dagbag.py:540} INFO - Filling up the DagBag from /opt/airflow/dags/dag_main.py
[2024-05-15T01:00:01.107+0000] {logging_mixin.py:188} INFO - [2024-05-15T01:00:01.102+0000] {dagbag.py:350} ERROR - Failed to import: /opt/airflow/dags/dag_main.py
Traceback (most recent call last):
  File "/home/airflow/.local/lib/python3.8/site-packages/airflow/models/dagbag.py", line 346, in parse
    loader.exec_module(new_module)
  File "<frozen importlib._bootstrap_external>", line 843, in exec_module
  File "<frozen importlib._bootstrap>", line 219, in _call_with_frames_removed
  File "/opt/airflow/dags/dag_main.py", line 6, in <module>
    from functions.class_data_validation import ValidateInputtedData
  File "/opt/airflow/dags/functions/class_data_validation.py", line 5, in <module>
    from function_data_validation import get_data, validate_data
ModuleNotFoundError: No module named 'function_data_validation'
[2024-05-15T01:00:01.109+0000] {processor.py:842} WARNING - No viable dags retrieved from /opt/airflow/dags/dag_main.py
[2024-05-15T01:00:01.129+0000] {processor.py:183} INFO - Processing /opt/airflow/dags/dag_main.py took 0.109 seconds
[2024-05-15T01:00:31.438+0000] {processor.py:161} INFO - Started process (PID=70) to work on /opt/airflow/dags/dag_main.py
[2024-05-15T01:00:31.439+0000] {processor.py:830} INFO - Processing file /opt/airflow/dags/dag_main.py for tasks to queue
[2024-05-15T01:00:31.441+0000] {logging_mixin.py:188} INFO - [2024-05-15T01:00:31.441+0000] {dagbag.py:540} INFO - Filling up the DagBag from /opt/airflow/dags/dag_main.py
[2024-05-15T01:00:31.529+0000] {logging_mixin.py:188} INFO - [2024-05-15T01:00:31.524+0000] {dagbag.py:350} ERROR - Failed to import: /opt/airflow/dags/dag_main.py
Traceback (most recent call last):
  File "/home/airflow/.local/lib/python3.8/site-packages/airflow/models/dagbag.py", line 346, in parse
    loader.exec_module(new_module)
  File "<frozen importlib._bootstrap_external>", line 843, in exec_module
  File "<frozen importlib._bootstrap>", line 219, in _call_with_frames_removed
  File "/opt/airflow/dags/dag_main.py", line 6, in <module>
    from functions.class_data_validation import ValidateInputtedData
  File "/opt/airflow/dags/functions/class_data_validation.py", line 5, in <module>
    from function_data_validation.py import get_data, validate_data
ModuleNotFoundError: No module named 'function_data_validation'
[2024-05-15T01:00:31.531+0000] {processor.py:842} WARNING - No viable dags retrieved from /opt/airflow/dags/dag_main.py
[2024-05-15T01:00:31.551+0000] {processor.py:183} INFO - Processing /opt/airflow/dags/dag_main.py took 0.116 seconds
[2024-05-15T01:01:01.846+0000] {processor.py:161} INFO - Started process (PID=79) to work on /opt/airflow/dags/dag_main.py
[2024-05-15T01:01:01.847+0000] {processor.py:830} INFO - Processing file /opt/airflow/dags/dag_main.py for tasks to queue
[2024-05-15T01:01:01.848+0000] {logging_mixin.py:188} INFO - [2024-05-15T01:01:01.848+0000] {dagbag.py:540} INFO - Filling up the DagBag from /opt/airflow/dags/dag_main.py
[2024-05-15T01:01:01.922+0000] {logging_mixin.py:188} INFO - [2024-05-15T01:01:01.917+0000] {dagbag.py:350} ERROR - Failed to import: /opt/airflow/dags/dag_main.py
Traceback (most recent call last):
  File "/home/airflow/.local/lib/python3.8/site-packages/airflow/models/dagbag.py", line 346, in parse
    loader.exec_module(new_module)
  File "<frozen importlib._bootstrap_external>", line 843, in exec_module
  File "<frozen importlib._bootstrap>", line 219, in _call_with_frames_removed
  File "/opt/airflow/dags/dag_main.py", line 6, in <module>
    from functions.class_data_validation import ValidateInputtedData
  File "/opt/airflow/dags/functions/class_data_validation.py", line 5, in <module>
    from function_data_validation.py import get_data, validate_data
ModuleNotFoundError: No module named 'function_data_validation'
[2024-05-15T01:01:01.924+0000] {processor.py:842} WARNING - No viable dags retrieved from /opt/airflow/dags/dag_main.py
[2024-05-15T01:01:01.943+0000] {processor.py:183} INFO - Processing /opt/airflow/dags/dag_main.py took 0.100 seconds
[2024-05-15T01:01:32.217+0000] {processor.py:161} INFO - Started process (PID=88) to work on /opt/airflow/dags/dag_main.py
[2024-05-15T01:01:32.218+0000] {processor.py:830} INFO - Processing file /opt/airflow/dags/dag_main.py for tasks to queue
[2024-05-15T01:01:32.220+0000] {logging_mixin.py:188} INFO - [2024-05-15T01:01:32.220+0000] {dagbag.py:540} INFO - Filling up the DagBag from /opt/airflow/dags/dag_main.py
[2024-05-15T01:01:32.286+0000] {logging_mixin.py:188} INFO - [2024-05-15T01:01:32.282+0000] {dagbag.py:350} ERROR - Failed to import: /opt/airflow/dags/dag_main.py
Traceback (most recent call last):
  File "/home/airflow/.local/lib/python3.8/site-packages/airflow/models/dagbag.py", line 346, in parse
    loader.exec_module(new_module)
  File "<frozen importlib._bootstrap_external>", line 843, in exec_module
  File "<frozen importlib._bootstrap>", line 219, in _call_with_frames_removed
  File "/opt/airflow/dags/dag_main.py", line 6, in <module>
    from functions.class_data_validation import ValidateInputtedData
  File "/opt/airflow/dags/functions/class_data_validation.py", line 5, in <module>
    from function_data_validation.py import get_data, validate_data
ModuleNotFoundError: No module named 'function_data_validation'
[2024-05-15T01:01:32.288+0000] {processor.py:842} WARNING - No viable dags retrieved from /opt/airflow/dags/dag_main.py
[2024-05-15T01:01:32.305+0000] {processor.py:183} INFO - Processing /opt/airflow/dags/dag_main.py took 0.090 seconds
[2024-05-15T01:02:02.574+0000] {processor.py:161} INFO - Started process (PID=97) to work on /opt/airflow/dags/dag_main.py
[2024-05-15T01:02:02.575+0000] {processor.py:830} INFO - Processing file /opt/airflow/dags/dag_main.py for tasks to queue
[2024-05-15T01:02:02.576+0000] {logging_mixin.py:188} INFO - [2024-05-15T01:02:02.576+0000] {dagbag.py:540} INFO - Filling up the DagBag from /opt/airflow/dags/dag_main.py
[2024-05-15T01:02:02.663+0000] {logging_mixin.py:188} INFO - [2024-05-15T01:02:02.660+0000] {dagbag.py:350} ERROR - Failed to import: /opt/airflow/dags/dag_main.py
Traceback (most recent call last):
  File "/home/airflow/.local/lib/python3.8/site-packages/airflow/models/dagbag.py", line 346, in parse
    loader.exec_module(new_module)
  File "<frozen importlib._bootstrap_external>", line 843, in exec_module
  File "<frozen importlib._bootstrap>", line 219, in _call_with_frames_removed
  File "/opt/airflow/dags/dag_main.py", line 24, in <module>
    validate_task = ValidateInputtedData(
  File "/home/airflow/.local/lib/python3.8/site-packages/airflow/models/baseoperator.py", line 423, in apply_defaults
    raise AirflowException(f"missing keyword arguments {display}")
airflow.exceptions.AirflowException: missing keyword arguments 'bucket_name', 'file_path'
[2024-05-15T01:02:02.664+0000] {processor.py:842} WARNING - No viable dags retrieved from /opt/airflow/dags/dag_main.py
[2024-05-15T01:02:02.681+0000] {processor.py:183} INFO - Processing /opt/airflow/dags/dag_main.py took 0.111 seconds
[2024-05-15T01:02:32.954+0000] {processor.py:161} INFO - Started process (PID=106) to work on /opt/airflow/dags/dag_main.py
[2024-05-15T01:02:32.954+0000] {processor.py:830} INFO - Processing file /opt/airflow/dags/dag_main.py for tasks to queue
[2024-05-15T01:02:32.956+0000] {logging_mixin.py:188} INFO - [2024-05-15T01:02:32.956+0000] {dagbag.py:540} INFO - Filling up the DagBag from /opt/airflow/dags/dag_main.py
[2024-05-15T01:02:34.101+0000] {logging_mixin.py:188} INFO - [2024-05-15T01:02:34.095+0000] {dagbag.py:350} ERROR - Failed to import: /opt/airflow/dags/dag_main.py
Traceback (most recent call last):
  File "/home/airflow/.local/lib/python3.8/site-packages/airflow/models/dagbag.py", line 346, in parse
    loader.exec_module(new_module)
  File "<frozen importlib._bootstrap_external>", line 843, in exec_module
  File "<frozen importlib._bootstrap>", line 219, in _call_with_frames_removed
  File "/opt/airflow/dags/dag_main.py", line 6, in <module>
    from functions.class_data_validation import ValidateInputtedData
  File "/opt/airflow/dags/functions/class_data_validation.py", line 6, in <module>
    import great_expectations as ge
ModuleNotFoundError: No module named 'great_expectations'
[2024-05-15T01:02:34.103+0000] {processor.py:842} WARNING - No viable dags retrieved from /opt/airflow/dags/dag_main.py
[2024-05-15T01:02:34.118+0000] {processor.py:183} INFO - Processing /opt/airflow/dags/dag_main.py took 1.167 seconds
[2024-05-15T01:03:04.468+0000] {processor.py:161} INFO - Started process (PID=117) to work on /opt/airflow/dags/dag_main.py
[2024-05-15T01:03:04.469+0000] {processor.py:830} INFO - Processing file /opt/airflow/dags/dag_main.py for tasks to queue
[2024-05-15T01:03:04.470+0000] {logging_mixin.py:188} INFO - [2024-05-15T01:03:04.470+0000] {dagbag.py:540} INFO - Filling up the DagBag from /opt/airflow/dags/dag_main.py
[2024-05-15T01:03:04.897+0000] {logging_mixin.py:188} INFO - [2024-05-15T01:03:04.891+0000] {dagbag.py:350} ERROR - Failed to import: /opt/airflow/dags/dag_main.py
Traceback (most recent call last):
  File "/home/airflow/.local/lib/python3.8/site-packages/airflow/models/dagbag.py", line 346, in parse
    loader.exec_module(new_module)
  File "<frozen importlib._bootstrap_external>", line 843, in exec_module
  File "<frozen importlib._bootstrap>", line 219, in _call_with_frames_removed
  File "/opt/airflow/dags/dag_main.py", line 6, in <module>
    from functions.class_data_validation import ValidateInputtedData
  File "/opt/airflow/dags/functions/class_data_validation.py", line 6, in <module>
    import great_expectations as ge
ModuleNotFoundError: No module named 'great_expectations'
[2024-05-15T01:03:04.898+0000] {processor.py:842} WARNING - No viable dags retrieved from /opt/airflow/dags/dag_main.py
[2024-05-15T01:03:04.913+0000] {processor.py:183} INFO - Processing /opt/airflow/dags/dag_main.py took 0.448 seconds
[2024-05-15T01:03:12.998+0000] {processor.py:161} INFO - Started process (PID=119) to work on /opt/airflow/dags/dag_main.py
[2024-05-15T01:03:12.999+0000] {processor.py:830} INFO - Processing file /opt/airflow/dags/dag_main.py for tasks to queue
[2024-05-15T01:03:13.001+0000] {logging_mixin.py:188} INFO - [2024-05-15T01:03:13.001+0000] {dagbag.py:540} INFO - Filling up the DagBag from /opt/airflow/dags/dag_main.py
[2024-05-15T01:03:13.428+0000] {logging_mixin.py:188} INFO - [2024-05-15T01:03:13.422+0000] {dagbag.py:350} ERROR - Failed to import: /opt/airflow/dags/dag_main.py
Traceback (most recent call last):
  File "/home/airflow/.local/lib/python3.8/site-packages/airflow/models/dagbag.py", line 346, in parse
    loader.exec_module(new_module)
  File "<frozen importlib._bootstrap_external>", line 843, in exec_module
  File "<frozen importlib._bootstrap>", line 219, in _call_with_frames_removed
  File "/opt/airflow/dags/dag_main.py", line 6, in <module>
    from functions.class_data_validation import ValidateInputtedData
  File "/opt/airflow/dags/functions/class_data_validation.py", line 6, in <module>
    import great_expectations as ge
ModuleNotFoundError: No module named 'great_expectations'
[2024-05-15T01:03:13.430+0000] {processor.py:842} WARNING - No viable dags retrieved from /opt/airflow/dags/dag_main.py
[2024-05-15T01:03:13.445+0000] {processor.py:183} INFO - Processing /opt/airflow/dags/dag_main.py took 0.450 seconds
[2024-05-15T01:03:14.011+0000] {processor.py:161} INFO - Started process (PID=121) to work on /opt/airflow/dags/dag_main.py
[2024-05-15T01:03:14.012+0000] {processor.py:830} INFO - Processing file /opt/airflow/dags/dag_main.py for tasks to queue
[2024-05-15T01:03:14.014+0000] {logging_mixin.py:188} INFO - [2024-05-15T01:03:14.014+0000] {dagbag.py:540} INFO - Filling up the DagBag from /opt/airflow/dags/dag_main.py
[2024-05-15T01:03:14.407+0000] {logging_mixin.py:188} INFO - [2024-05-15T01:03:14.400+0000] {dagbag.py:350} ERROR - Failed to import: /opt/airflow/dags/dag_main.py
Traceback (most recent call last):
  File "/home/airflow/.local/lib/python3.8/site-packages/airflow/models/dagbag.py", line 346, in parse
    loader.exec_module(new_module)
  File "<frozen importlib._bootstrap_external>", line 843, in exec_module
  File "<frozen importlib._bootstrap>", line 219, in _call_with_frames_removed
  File "/opt/airflow/dags/dag_main.py", line 6, in <module>
    from functions.class_data_validation import ValidateInputtedData
  File "/opt/airflow/dags/functions/class_data_validation.py", line 6, in <module>
    import great_expectations as ge
ModuleNotFoundError: No module named 'great_expectations'
[2024-05-15T01:03:14.409+0000] {processor.py:842} WARNING - No viable dags retrieved from /opt/airflow/dags/dag_main.py
[2024-05-15T01:03:14.427+0000] {processor.py:183} INFO - Processing /opt/airflow/dags/dag_main.py took 0.420 seconds
[2024-05-15T01:03:44.776+0000] {processor.py:161} INFO - Started process (PID=131) to work on /opt/airflow/dags/dag_main.py
[2024-05-15T01:03:44.777+0000] {processor.py:830} INFO - Processing file /opt/airflow/dags/dag_main.py for tasks to queue
[2024-05-15T01:03:44.779+0000] {logging_mixin.py:188} INFO - [2024-05-15T01:03:44.778+0000] {dagbag.py:540} INFO - Filling up the DagBag from /opt/airflow/dags/dag_main.py
[2024-05-15T01:03:45.203+0000] {logging_mixin.py:188} INFO - [2024-05-15T01:03:45.198+0000] {dagbag.py:350} ERROR - Failed to import: /opt/airflow/dags/dag_main.py
Traceback (most recent call last):
  File "/home/airflow/.local/lib/python3.8/site-packages/airflow/models/dagbag.py", line 346, in parse
    loader.exec_module(new_module)
  File "<frozen importlib._bootstrap_external>", line 843, in exec_module
  File "<frozen importlib._bootstrap>", line 219, in _call_with_frames_removed
  File "/opt/airflow/dags/dag_main.py", line 6, in <module>
    from functions.class_data_validation import ValidateInputtedData
  File "/opt/airflow/dags/functions/class_data_validation.py", line 6, in <module>
    import great_expectations as ge
ModuleNotFoundError: No module named 'great_expectations'
[2024-05-15T01:03:45.206+0000] {processor.py:842} WARNING - No viable dags retrieved from /opt/airflow/dags/dag_main.py
[2024-05-15T01:03:45.220+0000] {processor.py:183} INFO - Processing /opt/airflow/dags/dag_main.py took 0.447 seconds
[2024-05-15T01:04:15.254+0000] {processor.py:161} INFO - Started process (PID=141) to work on /opt/airflow/dags/dag_main.py
[2024-05-15T01:04:15.256+0000] {processor.py:830} INFO - Processing file /opt/airflow/dags/dag_main.py for tasks to queue
[2024-05-15T01:04:15.258+0000] {logging_mixin.py:188} INFO - [2024-05-15T01:04:15.258+0000] {dagbag.py:540} INFO - Filling up the DagBag from /opt/airflow/dags/dag_main.py
[2024-05-15T01:04:15.675+0000] {logging_mixin.py:188} INFO - [2024-05-15T01:04:15.670+0000] {dagbag.py:350} ERROR - Failed to import: /opt/airflow/dags/dag_main.py
Traceback (most recent call last):
  File "/home/airflow/.local/lib/python3.8/site-packages/airflow/models/dagbag.py", line 346, in parse
    loader.exec_module(new_module)
  File "<frozen importlib._bootstrap_external>", line 843, in exec_module
  File "<frozen importlib._bootstrap>", line 219, in _call_with_frames_removed
  File "/opt/airflow/dags/dag_main.py", line 6, in <module>
    from functions.class_data_validation import ValidateInputtedData
  File "/opt/airflow/dags/functions/class_data_validation.py", line 6, in <module>
    import great_expectations as ge
ModuleNotFoundError: No module named 'great_expectations'
[2024-05-15T01:04:15.677+0000] {processor.py:842} WARNING - No viable dags retrieved from /opt/airflow/dags/dag_main.py
[2024-05-15T01:04:15.691+0000] {processor.py:183} INFO - Processing /opt/airflow/dags/dag_main.py took 0.441 seconds
[2024-05-15T01:04:46.610+0000] {processor.py:161} INFO - Started process (PID=151) to work on /opt/airflow/dags/dag_main.py
[2024-05-15T01:04:46.611+0000] {processor.py:830} INFO - Processing file /opt/airflow/dags/dag_main.py for tasks to queue
[2024-05-15T01:04:46.613+0000] {logging_mixin.py:188} INFO - [2024-05-15T01:04:46.612+0000] {dagbag.py:540} INFO - Filling up the DagBag from /opt/airflow/dags/dag_main.py
[2024-05-15T01:04:46.887+0000] {logging_mixin.py:188} INFO - [2024-05-15T01:04:46.880+0000] {dagbag.py:350} ERROR - Failed to import: /opt/airflow/dags/dag_main.py
Traceback (most recent call last):
  File "/home/airflow/.local/lib/python3.8/site-packages/airflow/models/dagbag.py", line 346, in parse
    loader.exec_module(new_module)
  File "<frozen importlib._bootstrap_external>", line 843, in exec_module
  File "<frozen importlib._bootstrap>", line 219, in _call_with_frames_removed
  File "/opt/airflow/dags/dag_main.py", line 6, in <module>
    from functions.class_data_validation import ValidateInputtedData
  File "/opt/airflow/dags/functions/class_data_validation.py", line 6, in <module>
    import great_expectations as ge
ModuleNotFoundError: No module named 'great_expectations'
[2024-05-15T01:04:46.890+0000] {processor.py:842} WARNING - No viable dags retrieved from /opt/airflow/dags/dag_main.py
[2024-05-15T01:04:46.912+0000] {processor.py:183} INFO - Processing /opt/airflow/dags/dag_main.py took 0.306 seconds
[2024-05-15T01:05:16.999+0000] {processor.py:161} INFO - Started process (PID=161) to work on /opt/airflow/dags/dag_main.py
[2024-05-15T01:05:17.000+0000] {processor.py:830} INFO - Processing file /opt/airflow/dags/dag_main.py for tasks to queue
[2024-05-15T01:05:17.002+0000] {logging_mixin.py:188} INFO - [2024-05-15T01:05:17.002+0000] {dagbag.py:540} INFO - Filling up the DagBag from /opt/airflow/dags/dag_main.py
[2024-05-15T01:05:17.281+0000] {logging_mixin.py:188} INFO - [2024-05-15T01:05:17.276+0000] {dagbag.py:350} ERROR - Failed to import: /opt/airflow/dags/dag_main.py
Traceback (most recent call last):
  File "/home/airflow/.local/lib/python3.8/site-packages/airflow/models/dagbag.py", line 346, in parse
    loader.exec_module(new_module)
  File "<frozen importlib._bootstrap_external>", line 843, in exec_module
  File "<frozen importlib._bootstrap>", line 219, in _call_with_frames_removed
  File "/opt/airflow/dags/dag_main.py", line 6, in <module>
    from functions.class_data_validation import ValidateInputtedData
  File "/opt/airflow/dags/functions/class_data_validation.py", line 6, in <module>
    import great_expectations as ge
ModuleNotFoundError: No module named 'great_expectations'
[2024-05-15T01:05:17.283+0000] {processor.py:842} WARNING - No viable dags retrieved from /opt/airflow/dags/dag_main.py
[2024-05-15T01:05:17.298+0000] {processor.py:183} INFO - Processing /opt/airflow/dags/dag_main.py took 0.302 seconds
[2024-05-15T01:05:47.373+0000] {processor.py:161} INFO - Started process (PID=171) to work on /opt/airflow/dags/dag_main.py
[2024-05-15T01:05:47.374+0000] {processor.py:830} INFO - Processing file /opt/airflow/dags/dag_main.py for tasks to queue
[2024-05-15T01:05:47.376+0000] {logging_mixin.py:188} INFO - [2024-05-15T01:05:47.375+0000] {dagbag.py:540} INFO - Filling up the DagBag from /opt/airflow/dags/dag_main.py
[2024-05-15T01:05:47.767+0000] {logging_mixin.py:188} INFO - [2024-05-15T01:05:47.759+0000] {dagbag.py:350} ERROR - Failed to import: /opt/airflow/dags/dag_main.py
Traceback (most recent call last):
  File "/home/airflow/.local/lib/python3.8/site-packages/airflow/models/dagbag.py", line 346, in parse
    loader.exec_module(new_module)
  File "<frozen importlib._bootstrap_external>", line 843, in exec_module
  File "<frozen importlib._bootstrap>", line 219, in _call_with_frames_removed
  File "/opt/airflow/dags/dag_main.py", line 6, in <module>
    from functions.class_data_validation import ValidateInputtedData
  File "/opt/airflow/dags/functions/class_data_validation.py", line 6, in <module>
    import great_expectations as ge
ModuleNotFoundError: No module named 'great_expectations'
[2024-05-15T01:05:47.769+0000] {processor.py:842} WARNING - No viable dags retrieved from /opt/airflow/dags/dag_main.py
[2024-05-15T01:05:47.782+0000] {processor.py:183} INFO - Processing /opt/airflow/dags/dag_main.py took 0.413 seconds
[2024-05-15T01:06:18.761+0000] {processor.py:161} INFO - Started process (PID=187) to work on /opt/airflow/dags/dag_main.py
[2024-05-15T01:06:18.762+0000] {processor.py:830} INFO - Processing file /opt/airflow/dags/dag_main.py for tasks to queue
[2024-05-15T01:06:18.764+0000] {logging_mixin.py:188} INFO - [2024-05-15T01:06:18.764+0000] {dagbag.py:540} INFO - Filling up the DagBag from /opt/airflow/dags/dag_main.py
[2024-05-15T01:06:19.163+0000] {logging_mixin.py:188} INFO - [2024-05-15T01:06:19.158+0000] {dagbag.py:350} ERROR - Failed to import: /opt/airflow/dags/dag_main.py
Traceback (most recent call last):
  File "/home/airflow/.local/lib/python3.8/site-packages/airflow/models/dagbag.py", line 346, in parse
    loader.exec_module(new_module)
  File "<frozen importlib._bootstrap_external>", line 843, in exec_module
  File "<frozen importlib._bootstrap>", line 219, in _call_with_frames_removed
  File "/opt/airflow/dags/dag_main.py", line 6, in <module>
    from functions.class_data_validation import ValidateInputtedData
  File "/opt/airflow/dags/functions/class_data_validation.py", line 6, in <module>
    import great_expectations as ge
ModuleNotFoundError: No module named 'great_expectations'
[2024-05-15T01:06:19.165+0000] {processor.py:842} WARNING - No viable dags retrieved from /opt/airflow/dags/dag_main.py
[2024-05-15T01:06:19.178+0000] {processor.py:183} INFO - Processing /opt/airflow/dags/dag_main.py took 0.420 seconds
[2024-05-15T01:06:50.154+0000] {processor.py:161} INFO - Started process (PID=197) to work on /opt/airflow/dags/dag_main.py
[2024-05-15T01:06:50.155+0000] {processor.py:830} INFO - Processing file /opt/airflow/dags/dag_main.py for tasks to queue
[2024-05-15T01:06:50.157+0000] {logging_mixin.py:188} INFO - [2024-05-15T01:06:50.157+0000] {dagbag.py:540} INFO - Filling up the DagBag from /opt/airflow/dags/dag_main.py
[2024-05-15T01:06:50.595+0000] {logging_mixin.py:188} INFO - [2024-05-15T01:06:50.590+0000] {dagbag.py:350} ERROR - Failed to import: /opt/airflow/dags/dag_main.py
Traceback (most recent call last):
  File "/home/airflow/.local/lib/python3.8/site-packages/airflow/models/dagbag.py", line 346, in parse
    loader.exec_module(new_module)
  File "<frozen importlib._bootstrap_external>", line 843, in exec_module
  File "<frozen importlib._bootstrap>", line 219, in _call_with_frames_removed
  File "/opt/airflow/dags/dag_main.py", line 6, in <module>
    from functions.class_data_validation import ValidateInputtedData
  File "/opt/airflow/dags/functions/class_data_validation.py", line 6, in <module>
    import great_expectations as ge
ModuleNotFoundError: No module named 'great_expectations'
[2024-05-15T01:06:50.597+0000] {processor.py:842} WARNING - No viable dags retrieved from /opt/airflow/dags/dag_main.py
[2024-05-15T01:06:50.617+0000] {processor.py:183} INFO - Processing /opt/airflow/dags/dag_main.py took 0.466 seconds
[2024-05-15T01:07:21.560+0000] {processor.py:161} INFO - Started process (PID=207) to work on /opt/airflow/dags/dag_main.py
[2024-05-15T01:07:21.561+0000] {processor.py:830} INFO - Processing file /opt/airflow/dags/dag_main.py for tasks to queue
[2024-05-15T01:07:21.563+0000] {logging_mixin.py:188} INFO - [2024-05-15T01:07:21.563+0000] {dagbag.py:540} INFO - Filling up the DagBag from /opt/airflow/dags/dag_main.py
[2024-05-15T01:07:22.042+0000] {logging_mixin.py:188} INFO - [2024-05-15T01:07:22.034+0000] {dagbag.py:350} ERROR - Failed to import: /opt/airflow/dags/dag_main.py
Traceback (most recent call last):
  File "/home/airflow/.local/lib/python3.8/site-packages/airflow/models/dagbag.py", line 346, in parse
    loader.exec_module(new_module)
  File "<frozen importlib._bootstrap_external>", line 843, in exec_module
  File "<frozen importlib._bootstrap>", line 219, in _call_with_frames_removed
  File "/opt/airflow/dags/dag_main.py", line 6, in <module>
    from functions.class_data_validation import ValidateInputtedData
  File "/opt/airflow/dags/functions/class_data_validation.py", line 6, in <module>
    import great_expectations as ge
ModuleNotFoundError: No module named 'great_expectations'
[2024-05-15T01:07:22.045+0000] {processor.py:842} WARNING - No viable dags retrieved from /opt/airflow/dags/dag_main.py
[2024-05-15T01:07:22.063+0000] {processor.py:183} INFO - Processing /opt/airflow/dags/dag_main.py took 0.508 seconds
[2024-05-15T01:07:52.985+0000] {processor.py:161} INFO - Started process (PID=217) to work on /opt/airflow/dags/dag_main.py
[2024-05-15T01:07:52.986+0000] {processor.py:830} INFO - Processing file /opt/airflow/dags/dag_main.py for tasks to queue
[2024-05-15T01:07:52.988+0000] {logging_mixin.py:188} INFO - [2024-05-15T01:07:52.987+0000] {dagbag.py:540} INFO - Filling up the DagBag from /opt/airflow/dags/dag_main.py
[2024-05-15T01:07:53.284+0000] {logging_mixin.py:188} INFO - [2024-05-15T01:07:53.279+0000] {dagbag.py:350} ERROR - Failed to import: /opt/airflow/dags/dag_main.py
Traceback (most recent call last):
  File "/home/airflow/.local/lib/python3.8/site-packages/airflow/models/dagbag.py", line 346, in parse
    loader.exec_module(new_module)
  File "<frozen importlib._bootstrap_external>", line 843, in exec_module
  File "<frozen importlib._bootstrap>", line 219, in _call_with_frames_removed
  File "/opt/airflow/dags/dag_main.py", line 6, in <module>
    from functions.class_data_validation import ValidateInputtedData
  File "/opt/airflow/dags/functions/class_data_validation.py", line 6, in <module>
    import great_expectations as ge
ModuleNotFoundError: No module named 'great_expectations'
[2024-05-15T01:07:53.286+0000] {processor.py:842} WARNING - No viable dags retrieved from /opt/airflow/dags/dag_main.py
[2024-05-15T01:07:53.302+0000] {processor.py:183} INFO - Processing /opt/airflow/dags/dag_main.py took 0.321 seconds
[2024-05-15T01:11:32.914+0000] {processor.py:161} INFO - Started process (PID=42) to work on /opt/airflow/dags/dag_main.py
[2024-05-15T01:11:32.915+0000] {processor.py:830} INFO - Processing file /opt/airflow/dags/dag_main.py for tasks to queue
[2024-05-15T01:11:32.919+0000] {logging_mixin.py:188} INFO - [2024-05-15T01:11:32.919+0000] {dagbag.py:540} INFO - Filling up the DagBag from /opt/airflow/dags/dag_main.py
[2024-05-15T01:11:34.427+0000] {logging_mixin.py:188} INFO - [2024-05-15T01:11:34.421+0000] {dagbag.py:350} ERROR - Failed to import: /opt/airflow/dags/dag_main.py
Traceback (most recent call last):
  File "/home/airflow/.local/lib/python3.8/site-packages/airflow/models/dagbag.py", line 346, in parse
    loader.exec_module(new_module)
  File "<frozen importlib._bootstrap_external>", line 843, in exec_module
  File "<frozen importlib._bootstrap>", line 219, in _call_with_frames_removed
  File "/opt/airflow/dags/dag_main.py", line 6, in <module>
    from functions.class_data_validation import ValidateInputtedData
  File "/opt/airflow/dags/functions/class_data_validation.py", line 6, in <module>
    import great_expectations as ge
ModuleNotFoundError: No module named 'great_expectations'
[2024-05-15T01:11:34.429+0000] {processor.py:842} WARNING - No viable dags retrieved from /opt/airflow/dags/dag_main.py
[2024-05-15T01:11:34.447+0000] {processor.py:183} INFO - Processing /opt/airflow/dags/dag_main.py took 1.540 seconds
[2024-05-15T01:12:04.681+0000] {processor.py:161} INFO - Started process (PID=53) to work on /opt/airflow/dags/dag_main.py
[2024-05-15T01:12:04.682+0000] {processor.py:830} INFO - Processing file /opt/airflow/dags/dag_main.py for tasks to queue
[2024-05-15T01:12:04.684+0000] {logging_mixin.py:188} INFO - [2024-05-15T01:12:04.683+0000] {dagbag.py:540} INFO - Filling up the DagBag from /opt/airflow/dags/dag_main.py
[2024-05-15T01:12:05.184+0000] {logging_mixin.py:188} INFO - [2024-05-15T01:12:05.176+0000] {dagbag.py:350} ERROR - Failed to import: /opt/airflow/dags/dag_main.py
Traceback (most recent call last):
  File "/home/airflow/.local/lib/python3.8/site-packages/airflow/models/dagbag.py", line 346, in parse
    loader.exec_module(new_module)
  File "<frozen importlib._bootstrap_external>", line 843, in exec_module
  File "<frozen importlib._bootstrap>", line 219, in _call_with_frames_removed
  File "/opt/airflow/dags/dag_main.py", line 6, in <module>
    from functions.class_data_validation import ValidateInputtedData
  File "/opt/airflow/dags/functions/class_data_validation.py", line 6, in <module>
    import great_expectations as ge
ModuleNotFoundError: No module named 'great_expectations'
[2024-05-15T01:12:05.186+0000] {processor.py:842} WARNING - No viable dags retrieved from /opt/airflow/dags/dag_main.py
[2024-05-15T01:12:05.206+0000] {processor.py:183} INFO - Processing /opt/airflow/dags/dag_main.py took 0.528 seconds
[2024-05-15T01:12:36.022+0000] {processor.py:161} INFO - Started process (PID=64) to work on /opt/airflow/dags/dag_main.py
[2024-05-15T01:12:36.023+0000] {processor.py:830} INFO - Processing file /opt/airflow/dags/dag_main.py for tasks to queue
[2024-05-15T01:12:36.025+0000] {logging_mixin.py:188} INFO - [2024-05-15T01:12:36.025+0000] {dagbag.py:540} INFO - Filling up the DagBag from /opt/airflow/dags/dag_main.py
[2024-05-15T01:12:36.464+0000] {logging_mixin.py:188} INFO - [2024-05-15T01:12:36.458+0000] {dagbag.py:350} ERROR - Failed to import: /opt/airflow/dags/dag_main.py
Traceback (most recent call last):
  File "/home/airflow/.local/lib/python3.8/site-packages/airflow/models/dagbag.py", line 346, in parse
    loader.exec_module(new_module)
  File "<frozen importlib._bootstrap_external>", line 843, in exec_module
  File "<frozen importlib._bootstrap>", line 219, in _call_with_frames_removed
  File "/opt/airflow/dags/dag_main.py", line 6, in <module>
    from functions.class_data_validation import ValidateInputtedData
  File "/opt/airflow/dags/functions/class_data_validation.py", line 6, in <module>
    import great_expectations as ge
ModuleNotFoundError: No module named 'great_expectations'
[2024-05-15T01:12:36.465+0000] {processor.py:842} WARNING - No viable dags retrieved from /opt/airflow/dags/dag_main.py
[2024-05-15T01:12:36.480+0000] {processor.py:183} INFO - Processing /opt/airflow/dags/dag_main.py took 0.461 seconds
[2024-05-15T01:13:07.364+0000] {processor.py:161} INFO - Started process (PID=74) to work on /opt/airflow/dags/dag_main.py
[2024-05-15T01:13:07.364+0000] {processor.py:830} INFO - Processing file /opt/airflow/dags/dag_main.py for tasks to queue
[2024-05-15T01:13:07.366+0000] {logging_mixin.py:188} INFO - [2024-05-15T01:13:07.366+0000] {dagbag.py:540} INFO - Filling up the DagBag from /opt/airflow/dags/dag_main.py
[2024-05-15T01:13:07.770+0000] {logging_mixin.py:188} INFO - [2024-05-15T01:13:07.764+0000] {dagbag.py:350} ERROR - Failed to import: /opt/airflow/dags/dag_main.py
Traceback (most recent call last):
  File "/home/airflow/.local/lib/python3.8/site-packages/airflow/models/dagbag.py", line 346, in parse
    loader.exec_module(new_module)
  File "<frozen importlib._bootstrap_external>", line 843, in exec_module
  File "<frozen importlib._bootstrap>", line 219, in _call_with_frames_removed
  File "/opt/airflow/dags/dag_main.py", line 6, in <module>
    from functions.class_data_validation import ValidateInputtedData
  File "/opt/airflow/dags/functions/class_data_validation.py", line 6, in <module>
    import great_expectations as ge
ModuleNotFoundError: No module named 'great_expectations'
[2024-05-15T01:13:07.772+0000] {processor.py:842} WARNING - No viable dags retrieved from /opt/airflow/dags/dag_main.py
[2024-05-15T01:13:07.789+0000] {processor.py:183} INFO - Processing /opt/airflow/dags/dag_main.py took 0.428 seconds
[2024-05-15T01:13:37.847+0000] {processor.py:161} INFO - Started process (PID=84) to work on /opt/airflow/dags/dag_main.py
[2024-05-15T01:13:37.848+0000] {processor.py:830} INFO - Processing file /opt/airflow/dags/dag_main.py for tasks to queue
[2024-05-15T01:13:37.850+0000] {logging_mixin.py:188} INFO - [2024-05-15T01:13:37.849+0000] {dagbag.py:540} INFO - Filling up the DagBag from /opt/airflow/dags/dag_main.py
[2024-05-15T01:13:38.244+0000] {logging_mixin.py:188} INFO - [2024-05-15T01:13:38.235+0000] {dagbag.py:350} ERROR - Failed to import: /opt/airflow/dags/dag_main.py
Traceback (most recent call last):
  File "/home/airflow/.local/lib/python3.8/site-packages/airflow/models/dagbag.py", line 346, in parse
    loader.exec_module(new_module)
  File "<frozen importlib._bootstrap_external>", line 843, in exec_module
  File "<frozen importlib._bootstrap>", line 219, in _call_with_frames_removed
  File "/opt/airflow/dags/dag_main.py", line 6, in <module>
    from functions.class_data_validation import ValidateInputtedData
  File "/opt/airflow/dags/functions/class_data_validation.py", line 6, in <module>
    import great_expectations as ge
ModuleNotFoundError: No module named 'great_expectations'
[2024-05-15T01:13:38.246+0000] {processor.py:842} WARNING - No viable dags retrieved from /opt/airflow/dags/dag_main.py
[2024-05-15T01:13:38.258+0000] {processor.py:183} INFO - Processing /opt/airflow/dags/dag_main.py took 0.414 seconds
[2024-05-15T01:14:09.154+0000] {processor.py:161} INFO - Started process (PID=94) to work on /opt/airflow/dags/dag_main.py
[2024-05-15T01:14:09.155+0000] {processor.py:830} INFO - Processing file /opt/airflow/dags/dag_main.py for tasks to queue
[2024-05-15T01:14:09.157+0000] {logging_mixin.py:188} INFO - [2024-05-15T01:14:09.157+0000] {dagbag.py:540} INFO - Filling up the DagBag from /opt/airflow/dags/dag_main.py
[2024-05-15T01:14:09.535+0000] {logging_mixin.py:188} INFO - [2024-05-15T01:14:09.529+0000] {dagbag.py:350} ERROR - Failed to import: /opt/airflow/dags/dag_main.py
Traceback (most recent call last):
  File "/home/airflow/.local/lib/python3.8/site-packages/airflow/models/dagbag.py", line 346, in parse
    loader.exec_module(new_module)
  File "<frozen importlib._bootstrap_external>", line 843, in exec_module
  File "<frozen importlib._bootstrap>", line 219, in _call_with_frames_removed
  File "/opt/airflow/dags/dag_main.py", line 6, in <module>
    from functions.class_data_validation import ValidateInputtedData
  File "/opt/airflow/dags/functions/class_data_validation.py", line 6, in <module>
    import great_expectations as ge
ModuleNotFoundError: No module named 'great_expectations'
[2024-05-15T01:14:09.537+0000] {processor.py:842} WARNING - No viable dags retrieved from /opt/airflow/dags/dag_main.py
[2024-05-15T01:14:09.550+0000] {processor.py:183} INFO - Processing /opt/airflow/dags/dag_main.py took 0.399 seconds
[2024-05-15T01:14:40.481+0000] {processor.py:161} INFO - Started process (PID=104) to work on /opt/airflow/dags/dag_main.py
[2024-05-15T01:14:40.482+0000] {processor.py:830} INFO - Processing file /opt/airflow/dags/dag_main.py for tasks to queue
[2024-05-15T01:14:40.484+0000] {logging_mixin.py:188} INFO - [2024-05-15T01:14:40.483+0000] {dagbag.py:540} INFO - Filling up the DagBag from /opt/airflow/dags/dag_main.py
[2024-05-15T01:14:40.803+0000] {logging_mixin.py:188} INFO - [2024-05-15T01:14:40.798+0000] {dagbag.py:350} ERROR - Failed to import: /opt/airflow/dags/dag_main.py
Traceback (most recent call last):
  File "/home/airflow/.local/lib/python3.8/site-packages/airflow/models/dagbag.py", line 346, in parse
    loader.exec_module(new_module)
  File "<frozen importlib._bootstrap_external>", line 843, in exec_module
  File "<frozen importlib._bootstrap>", line 219, in _call_with_frames_removed
  File "/opt/airflow/dags/dag_main.py", line 6, in <module>
    from functions.class_data_validation import ValidateInputtedData
  File "/opt/airflow/dags/functions/class_data_validation.py", line 6, in <module>
    import great_expectations as ge
ModuleNotFoundError: No module named 'great_expectations'
[2024-05-15T01:14:40.805+0000] {processor.py:842} WARNING - No viable dags retrieved from /opt/airflow/dags/dag_main.py
[2024-05-15T01:14:40.848+0000] {processor.py:183} INFO - Processing /opt/airflow/dags/dag_main.py took 0.370 seconds
[2024-05-15T01:15:10.931+0000] {processor.py:161} INFO - Started process (PID=114) to work on /opt/airflow/dags/dag_main.py
[2024-05-15T01:15:10.932+0000] {processor.py:830} INFO - Processing file /opt/airflow/dags/dag_main.py for tasks to queue
[2024-05-15T01:15:10.933+0000] {logging_mixin.py:188} INFO - [2024-05-15T01:15:10.933+0000] {dagbag.py:540} INFO - Filling up the DagBag from /opt/airflow/dags/dag_main.py
[2024-05-15T01:15:11.390+0000] {logging_mixin.py:188} INFO - [2024-05-15T01:15:11.382+0000] {dagbag.py:350} ERROR - Failed to import: /opt/airflow/dags/dag_main.py
Traceback (most recent call last):
  File "/home/airflow/.local/lib/python3.8/site-packages/airflow/models/dagbag.py", line 346, in parse
    loader.exec_module(new_module)
  File "<frozen importlib._bootstrap_external>", line 843, in exec_module
  File "<frozen importlib._bootstrap>", line 219, in _call_with_frames_removed
  File "/opt/airflow/dags/dag_main.py", line 6, in <module>
    from functions.class_data_validation import ValidateInputtedData
  File "/opt/airflow/dags/functions/class_data_validation.py", line 6, in <module>
    import great_expectations as ge
ModuleNotFoundError: No module named 'great_expectations'
[2024-05-15T01:15:11.392+0000] {processor.py:842} WARNING - No viable dags retrieved from /opt/airflow/dags/dag_main.py
[2024-05-15T01:15:11.417+0000] {processor.py:183} INFO - Processing /opt/airflow/dags/dag_main.py took 0.490 seconds
[2024-05-15T01:15:42.177+0000] {processor.py:161} INFO - Started process (PID=124) to work on /opt/airflow/dags/dag_main.py
[2024-05-15T01:15:42.178+0000] {processor.py:830} INFO - Processing file /opt/airflow/dags/dag_main.py for tasks to queue
[2024-05-15T01:15:42.180+0000] {logging_mixin.py:188} INFO - [2024-05-15T01:15:42.179+0000] {dagbag.py:540} INFO - Filling up the DagBag from /opt/airflow/dags/dag_main.py
[2024-05-15T01:15:42.592+0000] {logging_mixin.py:188} INFO - [2024-05-15T01:15:42.587+0000] {dagbag.py:350} ERROR - Failed to import: /opt/airflow/dags/dag_main.py
Traceback (most recent call last):
  File "/home/airflow/.local/lib/python3.8/site-packages/airflow/models/dagbag.py", line 346, in parse
    loader.exec_module(new_module)
  File "<frozen importlib._bootstrap_external>", line 843, in exec_module
  File "<frozen importlib._bootstrap>", line 219, in _call_with_frames_removed
  File "/opt/airflow/dags/dag_main.py", line 6, in <module>
    from functions.class_data_validation import ValidateInputtedData
  File "/opt/airflow/dags/functions/class_data_validation.py", line 6, in <module>
    import great_expectations as ge
ModuleNotFoundError: No module named 'great_expectations'
[2024-05-15T01:15:42.594+0000] {processor.py:842} WARNING - No viable dags retrieved from /opt/airflow/dags/dag_main.py
[2024-05-15T01:15:42.612+0000] {processor.py:183} INFO - Processing /opt/airflow/dags/dag_main.py took 0.438 seconds
[2024-05-15T01:16:13.508+0000] {processor.py:161} INFO - Started process (PID=134) to work on /opt/airflow/dags/dag_main.py
[2024-05-15T01:16:13.510+0000] {processor.py:830} INFO - Processing file /opt/airflow/dags/dag_main.py for tasks to queue
[2024-05-15T01:16:13.512+0000] {logging_mixin.py:188} INFO - [2024-05-15T01:16:13.511+0000] {dagbag.py:540} INFO - Filling up the DagBag from /opt/airflow/dags/dag_main.py
[2024-05-15T01:16:13.899+0000] {logging_mixin.py:188} INFO - [2024-05-15T01:16:13.893+0000] {dagbag.py:350} ERROR - Failed to import: /opt/airflow/dags/dag_main.py
Traceback (most recent call last):
  File "/home/airflow/.local/lib/python3.8/site-packages/airflow/models/dagbag.py", line 346, in parse
    loader.exec_module(new_module)
  File "<frozen importlib._bootstrap_external>", line 843, in exec_module
  File "<frozen importlib._bootstrap>", line 219, in _call_with_frames_removed
  File "/opt/airflow/dags/dag_main.py", line 6, in <module>
    from functions.class_data_validation import ValidateInputtedData
  File "/opt/airflow/dags/functions/class_data_validation.py", line 6, in <module>
    import great_expectations as ge
ModuleNotFoundError: No module named 'great_expectations'
[2024-05-15T01:16:13.901+0000] {processor.py:842} WARNING - No viable dags retrieved from /opt/airflow/dags/dag_main.py
[2024-05-15T01:16:13.915+0000] {processor.py:183} INFO - Processing /opt/airflow/dags/dag_main.py took 0.410 seconds
[2024-05-15T01:16:43.964+0000] {processor.py:161} INFO - Started process (PID=144) to work on /opt/airflow/dags/dag_main.py
[2024-05-15T01:16:43.965+0000] {processor.py:830} INFO - Processing file /opt/airflow/dags/dag_main.py for tasks to queue
[2024-05-15T01:16:43.967+0000] {logging_mixin.py:188} INFO - [2024-05-15T01:16:43.966+0000] {dagbag.py:540} INFO - Filling up the DagBag from /opt/airflow/dags/dag_main.py
[2024-05-15T01:16:44.351+0000] {logging_mixin.py:188} INFO - [2024-05-15T01:16:44.345+0000] {dagbag.py:350} ERROR - Failed to import: /opt/airflow/dags/dag_main.py
Traceback (most recent call last):
  File "/home/airflow/.local/lib/python3.8/site-packages/airflow/models/dagbag.py", line 346, in parse
    loader.exec_module(new_module)
  File "<frozen importlib._bootstrap_external>", line 843, in exec_module
  File "<frozen importlib._bootstrap>", line 219, in _call_with_frames_removed
  File "/opt/airflow/dags/dag_main.py", line 6, in <module>
    from functions.class_data_validation import ValidateInputtedData
  File "/opt/airflow/dags/functions/class_data_validation.py", line 6, in <module>
    import great_expectations as ge
ModuleNotFoundError: No module named 'great_expectations'
[2024-05-15T01:16:44.353+0000] {processor.py:842} WARNING - No viable dags retrieved from /opt/airflow/dags/dag_main.py
[2024-05-15T01:16:44.366+0000] {processor.py:183} INFO - Processing /opt/airflow/dags/dag_main.py took 0.405 seconds
[2024-05-15T01:17:15.205+0000] {processor.py:161} INFO - Started process (PID=154) to work on /opt/airflow/dags/dag_main.py
[2024-05-15T01:17:15.206+0000] {processor.py:830} INFO - Processing file /opt/airflow/dags/dag_main.py for tasks to queue
[2024-05-15T01:17:15.208+0000] {logging_mixin.py:188} INFO - [2024-05-15T01:17:15.208+0000] {dagbag.py:540} INFO - Filling up the DagBag from /opt/airflow/dags/dag_main.py
[2024-05-15T01:17:15.482+0000] {logging_mixin.py:188} INFO - [2024-05-15T01:17:15.477+0000] {dagbag.py:350} ERROR - Failed to import: /opt/airflow/dags/dag_main.py
Traceback (most recent call last):
  File "/home/airflow/.local/lib/python3.8/site-packages/airflow/models/dagbag.py", line 346, in parse
    loader.exec_module(new_module)
  File "<frozen importlib._bootstrap_external>", line 843, in exec_module
  File "<frozen importlib._bootstrap>", line 219, in _call_with_frames_removed
  File "/opt/airflow/dags/dag_main.py", line 6, in <module>
    from functions.class_data_validation import ValidateInputtedData
  File "/opt/airflow/dags/functions/class_data_validation.py", line 6, in <module>
    import great_expectations as ge
ModuleNotFoundError: No module named 'great_expectations'
[2024-05-15T01:17:15.484+0000] {processor.py:842} WARNING - No viable dags retrieved from /opt/airflow/dags/dag_main.py
[2024-05-15T01:17:15.499+0000] {processor.py:183} INFO - Processing /opt/airflow/dags/dag_main.py took 0.297 seconds
[2024-05-15T01:17:45.584+0000] {processor.py:161} INFO - Started process (PID=165) to work on /opt/airflow/dags/dag_main.py
[2024-05-15T01:17:45.585+0000] {processor.py:830} INFO - Processing file /opt/airflow/dags/dag_main.py for tasks to queue
[2024-05-15T01:17:45.587+0000] {logging_mixin.py:188} INFO - [2024-05-15T01:17:45.587+0000] {dagbag.py:540} INFO - Filling up the DagBag from /opt/airflow/dags/dag_main.py
[2024-05-15T01:17:45.883+0000] {logging_mixin.py:188} INFO - [2024-05-15T01:17:45.878+0000] {dagbag.py:350} ERROR - Failed to import: /opt/airflow/dags/dag_main.py
Traceback (most recent call last):
  File "/home/airflow/.local/lib/python3.8/site-packages/airflow/models/dagbag.py", line 346, in parse
    loader.exec_module(new_module)
  File "<frozen importlib._bootstrap_external>", line 843, in exec_module
  File "<frozen importlib._bootstrap>", line 219, in _call_with_frames_removed
  File "/opt/airflow/dags/dag_main.py", line 6, in <module>
    from functions.class_data_validation import ValidateInputtedData
  File "/opt/airflow/dags/functions/class_data_validation.py", line 6, in <module>
    import great_expectations as ge
ModuleNotFoundError: No module named 'great_expectations'
[2024-05-15T01:17:45.885+0000] {processor.py:842} WARNING - No viable dags retrieved from /opt/airflow/dags/dag_main.py
[2024-05-15T01:17:45.900+0000] {processor.py:183} INFO - Processing /opt/airflow/dags/dag_main.py took 0.319 seconds
[2024-05-15T01:18:16.823+0000] {processor.py:161} INFO - Started process (PID=175) to work on /opt/airflow/dags/dag_main.py
[2024-05-15T01:18:16.824+0000] {processor.py:830} INFO - Processing file /opt/airflow/dags/dag_main.py for tasks to queue
[2024-05-15T01:18:16.826+0000] {logging_mixin.py:188} INFO - [2024-05-15T01:18:16.826+0000] {dagbag.py:540} INFO - Filling up the DagBag from /opt/airflow/dags/dag_main.py
[2024-05-15T01:18:17.239+0000] {logging_mixin.py:188} INFO - [2024-05-15T01:18:17.233+0000] {dagbag.py:350} ERROR - Failed to import: /opt/airflow/dags/dag_main.py
Traceback (most recent call last):
  File "/home/airflow/.local/lib/python3.8/site-packages/airflow/models/dagbag.py", line 346, in parse
    loader.exec_module(new_module)
  File "<frozen importlib._bootstrap_external>", line 843, in exec_module
  File "<frozen importlib._bootstrap>", line 219, in _call_with_frames_removed
  File "/opt/airflow/dags/dag_main.py", line 6, in <module>
    from functions.class_data_validation import ValidateInputtedData
  File "/opt/airflow/dags/functions/class_data_validation.py", line 6, in <module>
    import great_expectations as ge
ModuleNotFoundError: No module named 'great_expectations'
[2024-05-15T01:18:17.241+0000] {processor.py:842} WARNING - No viable dags retrieved from /opt/airflow/dags/dag_main.py
[2024-05-15T01:18:17.258+0000] {processor.py:183} INFO - Processing /opt/airflow/dags/dag_main.py took 0.438 seconds
[2024-05-15T01:18:48.185+0000] {processor.py:161} INFO - Started process (PID=185) to work on /opt/airflow/dags/dag_main.py
[2024-05-15T01:18:48.186+0000] {processor.py:830} INFO - Processing file /opt/airflow/dags/dag_main.py for tasks to queue
[2024-05-15T01:18:48.188+0000] {logging_mixin.py:188} INFO - [2024-05-15T01:18:48.188+0000] {dagbag.py:540} INFO - Filling up the DagBag from /opt/airflow/dags/dag_main.py
[2024-05-15T01:18:48.616+0000] {logging_mixin.py:188} INFO - [2024-05-15T01:18:48.608+0000] {dagbag.py:350} ERROR - Failed to import: /opt/airflow/dags/dag_main.py
Traceback (most recent call last):
  File "/home/airflow/.local/lib/python3.8/site-packages/airflow/models/dagbag.py", line 346, in parse
    loader.exec_module(new_module)
  File "<frozen importlib._bootstrap_external>", line 843, in exec_module
  File "<frozen importlib._bootstrap>", line 219, in _call_with_frames_removed
  File "/opt/airflow/dags/dag_main.py", line 6, in <module>
    from functions.class_data_validation import ValidateInputtedData
  File "/opt/airflow/dags/functions/class_data_validation.py", line 6, in <module>
    import great_expectations as ge
ModuleNotFoundError: No module named 'great_expectations'
[2024-05-15T01:18:48.619+0000] {processor.py:842} WARNING - No viable dags retrieved from /opt/airflow/dags/dag_main.py
[2024-05-15T01:18:48.637+0000] {processor.py:183} INFO - Processing /opt/airflow/dags/dag_main.py took 0.455 seconds
[2024-05-15T01:19:19.495+0000] {processor.py:161} INFO - Started process (PID=201) to work on /opt/airflow/dags/dag_main.py
[2024-05-15T01:19:19.496+0000] {processor.py:830} INFO - Processing file /opt/airflow/dags/dag_main.py for tasks to queue
[2024-05-15T01:19:19.498+0000] {logging_mixin.py:188} INFO - [2024-05-15T01:19:19.498+0000] {dagbag.py:540} INFO - Filling up the DagBag from /opt/airflow/dags/dag_main.py
[2024-05-15T01:19:19.925+0000] {logging_mixin.py:188} INFO - [2024-05-15T01:19:19.919+0000] {dagbag.py:350} ERROR - Failed to import: /opt/airflow/dags/dag_main.py
Traceback (most recent call last):
  File "/home/airflow/.local/lib/python3.8/site-packages/airflow/models/dagbag.py", line 346, in parse
    loader.exec_module(new_module)
  File "<frozen importlib._bootstrap_external>", line 843, in exec_module
  File "<frozen importlib._bootstrap>", line 219, in _call_with_frames_removed
  File "/opt/airflow/dags/dag_main.py", line 6, in <module>
    from functions.class_data_validation import ValidateInputtedData
  File "/opt/airflow/dags/functions/class_data_validation.py", line 6, in <module>
    import great_expectations as ge
ModuleNotFoundError: No module named 'great_expectations'
[2024-05-15T01:19:19.927+0000] {processor.py:842} WARNING - No viable dags retrieved from /opt/airflow/dags/dag_main.py
[2024-05-15T01:19:19.942+0000] {processor.py:183} INFO - Processing /opt/airflow/dags/dag_main.py took 0.449 seconds
[2024-05-15T01:19:50.821+0000] {processor.py:161} INFO - Started process (PID=211) to work on /opt/airflow/dags/dag_main.py
[2024-05-15T01:19:50.822+0000] {processor.py:830} INFO - Processing file /opt/airflow/dags/dag_main.py for tasks to queue
[2024-05-15T01:19:50.825+0000] {logging_mixin.py:188} INFO - [2024-05-15T01:19:50.824+0000] {dagbag.py:540} INFO - Filling up the DagBag from /opt/airflow/dags/dag_main.py
[2024-05-15T01:19:51.276+0000] {logging_mixin.py:188} INFO - [2024-05-15T01:19:51.271+0000] {dagbag.py:350} ERROR - Failed to import: /opt/airflow/dags/dag_main.py
Traceback (most recent call last):
  File "/home/airflow/.local/lib/python3.8/site-packages/airflow/models/dagbag.py", line 346, in parse
    loader.exec_module(new_module)
  File "<frozen importlib._bootstrap_external>", line 843, in exec_module
  File "<frozen importlib._bootstrap>", line 219, in _call_with_frames_removed
  File "/opt/airflow/dags/dag_main.py", line 6, in <module>
    from functions.class_data_validation import ValidateInputtedData
  File "/opt/airflow/dags/functions/class_data_validation.py", line 6, in <module>
    import great_expectations as ge
ModuleNotFoundError: No module named 'great_expectations'
[2024-05-15T01:19:51.278+0000] {processor.py:842} WARNING - No viable dags retrieved from /opt/airflow/dags/dag_main.py
[2024-05-15T01:19:51.292+0000] {processor.py:183} INFO - Processing /opt/airflow/dags/dag_main.py took 0.476 seconds
[2024-05-15T01:20:22.129+0000] {processor.py:161} INFO - Started process (PID=221) to work on /opt/airflow/dags/dag_main.py
[2024-05-15T01:20:22.130+0000] {processor.py:830} INFO - Processing file /opt/airflow/dags/dag_main.py for tasks to queue
[2024-05-15T01:20:22.131+0000] {logging_mixin.py:188} INFO - [2024-05-15T01:20:22.131+0000] {dagbag.py:540} INFO - Filling up the DagBag from /opt/airflow/dags/dag_main.py
[2024-05-15T01:20:22.415+0000] {logging_mixin.py:188} INFO - [2024-05-15T01:20:22.409+0000] {dagbag.py:350} ERROR - Failed to import: /opt/airflow/dags/dag_main.py
Traceback (most recent call last):
  File "/home/airflow/.local/lib/python3.8/site-packages/airflow/models/dagbag.py", line 346, in parse
    loader.exec_module(new_module)
  File "<frozen importlib._bootstrap_external>", line 843, in exec_module
  File "<frozen importlib._bootstrap>", line 219, in _call_with_frames_removed
  File "/opt/airflow/dags/dag_main.py", line 6, in <module>
    from functions.class_data_validation import ValidateInputtedData
  File "/opt/airflow/dags/functions/class_data_validation.py", line 6, in <module>
    import great_expectations as ge
ModuleNotFoundError: No module named 'great_expectations'
[2024-05-15T01:20:22.417+0000] {processor.py:842} WARNING - No viable dags retrieved from /opt/airflow/dags/dag_main.py
[2024-05-15T01:20:22.433+0000] {processor.py:183} INFO - Processing /opt/airflow/dags/dag_main.py took 0.307 seconds
[2024-05-15T01:20:52.503+0000] {processor.py:161} INFO - Started process (PID=231) to work on /opt/airflow/dags/dag_main.py
[2024-05-15T01:20:52.504+0000] {processor.py:830} INFO - Processing file /opt/airflow/dags/dag_main.py for tasks to queue
[2024-05-15T01:20:52.507+0000] {logging_mixin.py:188} INFO - [2024-05-15T01:20:52.506+0000] {dagbag.py:540} INFO - Filling up the DagBag from /opt/airflow/dags/dag_main.py
[2024-05-15T01:20:52.828+0000] {logging_mixin.py:188} INFO - [2024-05-15T01:20:52.820+0000] {dagbag.py:350} ERROR - Failed to import: /opt/airflow/dags/dag_main.py
Traceback (most recent call last):
  File "/home/airflow/.local/lib/python3.8/site-packages/airflow/models/dagbag.py", line 346, in parse
    loader.exec_module(new_module)
  File "<frozen importlib._bootstrap_external>", line 843, in exec_module
  File "<frozen importlib._bootstrap>", line 219, in _call_with_frames_removed
  File "/opt/airflow/dags/dag_main.py", line 6, in <module>
    from functions.class_data_validation import ValidateInputtedData
  File "/opt/airflow/dags/functions/class_data_validation.py", line 6, in <module>
    import great_expectations as ge
ModuleNotFoundError: No module named 'great_expectations'
[2024-05-15T01:20:52.830+0000] {processor.py:842} WARNING - No viable dags retrieved from /opt/airflow/dags/dag_main.py
[2024-05-15T01:20:52.851+0000] {processor.py:183} INFO - Processing /opt/airflow/dags/dag_main.py took 0.351 seconds
[2024-05-15T01:21:22.924+0000] {processor.py:161} INFO - Started process (PID=241) to work on /opt/airflow/dags/dag_main.py
[2024-05-15T01:21:22.925+0000] {processor.py:830} INFO - Processing file /opt/airflow/dags/dag_main.py for tasks to queue
[2024-05-15T01:21:22.927+0000] {logging_mixin.py:188} INFO - [2024-05-15T01:21:22.926+0000] {dagbag.py:540} INFO - Filling up the DagBag from /opt/airflow/dags/dag_main.py
[2024-05-15T01:21:23.332+0000] {logging_mixin.py:188} INFO - [2024-05-15T01:21:23.327+0000] {dagbag.py:350} ERROR - Failed to import: /opt/airflow/dags/dag_main.py
Traceback (most recent call last):
  File "/home/airflow/.local/lib/python3.8/site-packages/airflow/models/dagbag.py", line 346, in parse
    loader.exec_module(new_module)
  File "<frozen importlib._bootstrap_external>", line 843, in exec_module
  File "<frozen importlib._bootstrap>", line 219, in _call_with_frames_removed
  File "/opt/airflow/dags/dag_main.py", line 6, in <module>
    from functions.class_data_validation import ValidateInputtedData
  File "/opt/airflow/dags/functions/class_data_validation.py", line 6, in <module>
    import great_expectations as ge
ModuleNotFoundError: No module named 'great_expectations'
[2024-05-15T01:21:23.334+0000] {processor.py:842} WARNING - No viable dags retrieved from /opt/airflow/dags/dag_main.py
[2024-05-15T01:21:23.348+0000] {processor.py:183} INFO - Processing /opt/airflow/dags/dag_main.py took 0.427 seconds
[2024-05-15T01:21:54.148+0000] {processor.py:161} INFO - Started process (PID=251) to work on /opt/airflow/dags/dag_main.py
[2024-05-15T01:21:54.149+0000] {processor.py:830} INFO - Processing file /opt/airflow/dags/dag_main.py for tasks to queue
[2024-05-15T01:21:54.151+0000] {logging_mixin.py:188} INFO - [2024-05-15T01:21:54.150+0000] {dagbag.py:540} INFO - Filling up the DagBag from /opt/airflow/dags/dag_main.py
[2024-05-15T01:21:54.542+0000] {logging_mixin.py:188} INFO - [2024-05-15T01:21:54.537+0000] {dagbag.py:350} ERROR - Failed to import: /opt/airflow/dags/dag_main.py
Traceback (most recent call last):
  File "/home/airflow/.local/lib/python3.8/site-packages/airflow/models/dagbag.py", line 346, in parse
    loader.exec_module(new_module)
  File "<frozen importlib._bootstrap_external>", line 843, in exec_module
  File "<frozen importlib._bootstrap>", line 219, in _call_with_frames_removed
  File "/opt/airflow/dags/dag_main.py", line 6, in <module>
    from functions.class_data_validation import ValidateInputtedData
  File "/opt/airflow/dags/functions/class_data_validation.py", line 6, in <module>
    import great_expectations as ge
ModuleNotFoundError: No module named 'great_expectations'
[2024-05-15T01:21:54.544+0000] {processor.py:842} WARNING - No viable dags retrieved from /opt/airflow/dags/dag_main.py
[2024-05-15T01:21:54.561+0000] {processor.py:183} INFO - Processing /opt/airflow/dags/dag_main.py took 0.416 seconds
[2024-05-15T01:22:25.493+0000] {processor.py:161} INFO - Started process (PID=261) to work on /opt/airflow/dags/dag_main.py
[2024-05-15T01:22:25.494+0000] {processor.py:830} INFO - Processing file /opt/airflow/dags/dag_main.py for tasks to queue
[2024-05-15T01:22:25.496+0000] {logging_mixin.py:188} INFO - [2024-05-15T01:22:25.496+0000] {dagbag.py:540} INFO - Filling up the DagBag from /opt/airflow/dags/dag_main.py
[2024-05-15T01:22:25.886+0000] {logging_mixin.py:188} INFO - [2024-05-15T01:22:25.878+0000] {dagbag.py:350} ERROR - Failed to import: /opt/airflow/dags/dag_main.py
Traceback (most recent call last):
  File "/home/airflow/.local/lib/python3.8/site-packages/airflow/models/dagbag.py", line 346, in parse
    loader.exec_module(new_module)
  File "<frozen importlib._bootstrap_external>", line 843, in exec_module
  File "<frozen importlib._bootstrap>", line 219, in _call_with_frames_removed
  File "/opt/airflow/dags/dag_main.py", line 6, in <module>
    from functions.class_data_validation import ValidateInputtedData
  File "/opt/airflow/dags/functions/class_data_validation.py", line 6, in <module>
    import great_expectations as ge
ModuleNotFoundError: No module named 'great_expectations'
[2024-05-15T01:22:25.888+0000] {processor.py:842} WARNING - No viable dags retrieved from /opt/airflow/dags/dag_main.py
[2024-05-15T01:22:25.901+0000] {processor.py:183} INFO - Processing /opt/airflow/dags/dag_main.py took 0.411 seconds
[2024-05-15T01:22:56.794+0000] {processor.py:161} INFO - Started process (PID=271) to work on /opt/airflow/dags/dag_main.py
[2024-05-15T01:22:56.795+0000] {processor.py:830} INFO - Processing file /opt/airflow/dags/dag_main.py for tasks to queue
[2024-05-15T01:22:56.798+0000] {logging_mixin.py:188} INFO - [2024-05-15T01:22:56.798+0000] {dagbag.py:540} INFO - Filling up the DagBag from /opt/airflow/dags/dag_main.py
[2024-05-15T01:22:57.195+0000] {logging_mixin.py:188} INFO - [2024-05-15T01:22:57.188+0000] {dagbag.py:350} ERROR - Failed to import: /opt/airflow/dags/dag_main.py
Traceback (most recent call last):
  File "/home/airflow/.local/lib/python3.8/site-packages/airflow/models/dagbag.py", line 346, in parse
    loader.exec_module(new_module)
  File "<frozen importlib._bootstrap_external>", line 843, in exec_module
  File "<frozen importlib._bootstrap>", line 219, in _call_with_frames_removed
  File "/opt/airflow/dags/dag_main.py", line 6, in <module>
    from functions.class_data_validation import ValidateInputtedData
  File "/opt/airflow/dags/functions/class_data_validation.py", line 6, in <module>
    import great_expectations as ge
ModuleNotFoundError: No module named 'great_expectations'
[2024-05-15T01:22:57.196+0000] {processor.py:842} WARNING - No viable dags retrieved from /opt/airflow/dags/dag_main.py
[2024-05-15T01:22:57.209+0000] {processor.py:183} INFO - Processing /opt/airflow/dags/dag_main.py took 0.418 seconds
[2024-05-15T01:26:15.751+0000] {processor.py:161} INFO - Started process (PID=42) to work on /opt/airflow/dags/dag_main.py
[2024-05-15T01:26:15.753+0000] {processor.py:830} INFO - Processing file /opt/airflow/dags/dag_main.py for tasks to queue
[2024-05-15T01:26:15.756+0000] {logging_mixin.py:188} INFO - [2024-05-15T01:26:15.756+0000] {dagbag.py:540} INFO - Filling up the DagBag from /opt/airflow/dags/dag_main.py
[2024-05-15T01:26:17.183+0000] {logging_mixin.py:188} INFO - [2024-05-15T01:26:17.177+0000] {dagbag.py:350} ERROR - Failed to import: /opt/airflow/dags/dag_main.py
Traceback (most recent call last):
  File "/home/airflow/.local/lib/python3.8/site-packages/airflow/models/dagbag.py", line 346, in parse
    loader.exec_module(new_module)
  File "<frozen importlib._bootstrap_external>", line 843, in exec_module
  File "<frozen importlib._bootstrap>", line 219, in _call_with_frames_removed
  File "/opt/airflow/dags/dag_main.py", line 6, in <module>
    from functions.class_data_validation import ValidateInputtedData
  File "/opt/airflow/dags/functions/class_data_validation.py", line 6, in <module>
    import great_expectations as ge
ModuleNotFoundError: No module named 'great_expectations'
[2024-05-15T01:26:17.185+0000] {processor.py:842} WARNING - No viable dags retrieved from /opt/airflow/dags/dag_main.py
[2024-05-15T01:26:17.204+0000] {processor.py:183} INFO - Processing /opt/airflow/dags/dag_main.py took 1.462 seconds
[2024-05-15T01:26:47.657+0000] {processor.py:161} INFO - Started process (PID=54) to work on /opt/airflow/dags/dag_main.py
[2024-05-15T01:26:47.659+0000] {processor.py:830} INFO - Processing file /opt/airflow/dags/dag_main.py for tasks to queue
[2024-05-15T01:26:47.661+0000] {logging_mixin.py:188} INFO - [2024-05-15T01:26:47.660+0000] {dagbag.py:540} INFO - Filling up the DagBag from /opt/airflow/dags/dag_main.py
[2024-05-15T01:26:48.161+0000] {logging_mixin.py:188} INFO - [2024-05-15T01:26:48.155+0000] {dagbag.py:350} ERROR - Failed to import: /opt/airflow/dags/dag_main.py
Traceback (most recent call last):
  File "/home/airflow/.local/lib/python3.8/site-packages/airflow/models/dagbag.py", line 346, in parse
    loader.exec_module(new_module)
  File "<frozen importlib._bootstrap_external>", line 843, in exec_module
  File "<frozen importlib._bootstrap>", line 219, in _call_with_frames_removed
  File "/opt/airflow/dags/dag_main.py", line 6, in <module>
    from functions.class_data_validation import ValidateInputtedData
  File "/opt/airflow/dags/functions/class_data_validation.py", line 6, in <module>
    import great_expectations as ge
ModuleNotFoundError: No module named 'great_expectations'
[2024-05-15T01:26:48.163+0000] {processor.py:842} WARNING - No viable dags retrieved from /opt/airflow/dags/dag_main.py
[2024-05-15T01:26:48.179+0000] {processor.py:183} INFO - Processing /opt/airflow/dags/dag_main.py took 0.524 seconds
[2024-05-15T01:27:19.106+0000] {processor.py:161} INFO - Started process (PID=64) to work on /opt/airflow/dags/dag_main.py
[2024-05-15T01:27:19.107+0000] {processor.py:830} INFO - Processing file /opt/airflow/dags/dag_main.py for tasks to queue
[2024-05-15T01:27:19.109+0000] {logging_mixin.py:188} INFO - [2024-05-15T01:27:19.109+0000] {dagbag.py:540} INFO - Filling up the DagBag from /opt/airflow/dags/dag_main.py
[2024-05-15T01:27:19.515+0000] {logging_mixin.py:188} INFO - [2024-05-15T01:27:19.510+0000] {dagbag.py:350} ERROR - Failed to import: /opt/airflow/dags/dag_main.py
Traceback (most recent call last):
  File "/home/airflow/.local/lib/python3.8/site-packages/airflow/models/dagbag.py", line 346, in parse
    loader.exec_module(new_module)
  File "<frozen importlib._bootstrap_external>", line 843, in exec_module
  File "<frozen importlib._bootstrap>", line 219, in _call_with_frames_removed
  File "/opt/airflow/dags/dag_main.py", line 6, in <module>
    from functions.class_data_validation import ValidateInputtedData
  File "/opt/airflow/dags/functions/class_data_validation.py", line 6, in <module>
    import great_expectations as ge
ModuleNotFoundError: No module named 'great_expectations'
[2024-05-15T01:27:19.516+0000] {processor.py:842} WARNING - No viable dags retrieved from /opt/airflow/dags/dag_main.py
[2024-05-15T01:27:19.530+0000] {processor.py:183} INFO - Processing /opt/airflow/dags/dag_main.py took 0.427 seconds
[2024-05-15T01:27:50.454+0000] {processor.py:161} INFO - Started process (PID=74) to work on /opt/airflow/dags/dag_main.py
[2024-05-15T01:27:50.455+0000] {processor.py:830} INFO - Processing file /opt/airflow/dags/dag_main.py for tasks to queue
[2024-05-15T01:27:50.457+0000] {logging_mixin.py:188} INFO - [2024-05-15T01:27:50.457+0000] {dagbag.py:540} INFO - Filling up the DagBag from /opt/airflow/dags/dag_main.py
[2024-05-15T01:27:50.882+0000] {logging_mixin.py:188} INFO - [2024-05-15T01:27:50.877+0000] {dagbag.py:350} ERROR - Failed to import: /opt/airflow/dags/dag_main.py
Traceback (most recent call last):
  File "/home/airflow/.local/lib/python3.8/site-packages/airflow/models/dagbag.py", line 346, in parse
    loader.exec_module(new_module)
  File "<frozen importlib._bootstrap_external>", line 843, in exec_module
  File "<frozen importlib._bootstrap>", line 219, in _call_with_frames_removed
  File "/opt/airflow/dags/dag_main.py", line 6, in <module>
    from functions.class_data_validation import ValidateInputtedData
  File "/opt/airflow/dags/functions/class_data_validation.py", line 6, in <module>
    import great_expectations as ge
ModuleNotFoundError: No module named 'great_expectations'
[2024-05-15T01:27:50.884+0000] {processor.py:842} WARNING - No viable dags retrieved from /opt/airflow/dags/dag_main.py
[2024-05-15T01:27:50.898+0000] {processor.py:183} INFO - Processing /opt/airflow/dags/dag_main.py took 0.447 seconds
[2024-05-15T01:28:21.858+0000] {processor.py:161} INFO - Started process (PID=84) to work on /opt/airflow/dags/dag_main.py
[2024-05-15T01:28:21.859+0000] {processor.py:830} INFO - Processing file /opt/airflow/dags/dag_main.py for tasks to queue
[2024-05-15T01:28:21.861+0000] {logging_mixin.py:188} INFO - [2024-05-15T01:28:21.861+0000] {dagbag.py:540} INFO - Filling up the DagBag from /opt/airflow/dags/dag_main.py
[2024-05-15T01:28:22.277+0000] {logging_mixin.py:188} INFO - [2024-05-15T01:28:22.272+0000] {dagbag.py:350} ERROR - Failed to import: /opt/airflow/dags/dag_main.py
Traceback (most recent call last):
  File "/home/airflow/.local/lib/python3.8/site-packages/airflow/models/dagbag.py", line 346, in parse
    loader.exec_module(new_module)
  File "<frozen importlib._bootstrap_external>", line 843, in exec_module
  File "<frozen importlib._bootstrap>", line 219, in _call_with_frames_removed
  File "/opt/airflow/dags/dag_main.py", line 6, in <module>
    from functions.class_data_validation import ValidateInputtedData
  File "/opt/airflow/dags/functions/class_data_validation.py", line 6, in <module>
    import great_expectations as ge
ModuleNotFoundError: No module named 'great_expectations'
[2024-05-15T01:28:22.278+0000] {processor.py:842} WARNING - No viable dags retrieved from /opt/airflow/dags/dag_main.py
[2024-05-15T01:28:22.293+0000] {processor.py:183} INFO - Processing /opt/airflow/dags/dag_main.py took 0.438 seconds
[2024-05-15T01:28:53.261+0000] {processor.py:161} INFO - Started process (PID=94) to work on /opt/airflow/dags/dag_main.py
[2024-05-15T01:28:53.262+0000] {processor.py:830} INFO - Processing file /opt/airflow/dags/dag_main.py for tasks to queue
[2024-05-15T01:28:53.263+0000] {logging_mixin.py:188} INFO - [2024-05-15T01:28:53.263+0000] {dagbag.py:540} INFO - Filling up the DagBag from /opt/airflow/dags/dag_main.py
[2024-05-15T01:28:53.535+0000] {logging_mixin.py:188} INFO - [2024-05-15T01:28:53.527+0000] {dagbag.py:350} ERROR - Failed to import: /opt/airflow/dags/dag_main.py
Traceback (most recent call last):
  File "/home/airflow/.local/lib/python3.8/site-packages/airflow/models/dagbag.py", line 346, in parse
    loader.exec_module(new_module)
  File "<frozen importlib._bootstrap_external>", line 843, in exec_module
  File "<frozen importlib._bootstrap>", line 219, in _call_with_frames_removed
  File "/opt/airflow/dags/dag_main.py", line 6, in <module>
    from functions.class_data_validation import ValidateInputtedData
  File "/opt/airflow/dags/functions/class_data_validation.py", line 6, in <module>
    import great_expectations as ge
ModuleNotFoundError: No module named 'great_expectations'
[2024-05-15T01:28:53.537+0000] {processor.py:842} WARNING - No viable dags retrieved from /opt/airflow/dags/dag_main.py
[2024-05-15T01:28:53.553+0000] {processor.py:183} INFO - Processing /opt/airflow/dags/dag_main.py took 0.295 seconds
[2024-05-15T01:29:23.633+0000] {processor.py:161} INFO - Started process (PID=104) to work on /opt/airflow/dags/dag_main.py
[2024-05-15T01:29:23.634+0000] {processor.py:830} INFO - Processing file /opt/airflow/dags/dag_main.py for tasks to queue
[2024-05-15T01:29:23.636+0000] {logging_mixin.py:188} INFO - [2024-05-15T01:29:23.636+0000] {dagbag.py:540} INFO - Filling up the DagBag from /opt/airflow/dags/dag_main.py
[2024-05-15T01:29:23.899+0000] {logging_mixin.py:188} INFO - [2024-05-15T01:29:23.894+0000] {dagbag.py:350} ERROR - Failed to import: /opt/airflow/dags/dag_main.py
Traceback (most recent call last):
  File "/home/airflow/.local/lib/python3.8/site-packages/airflow/models/dagbag.py", line 346, in parse
    loader.exec_module(new_module)
  File "<frozen importlib._bootstrap_external>", line 843, in exec_module
  File "<frozen importlib._bootstrap>", line 219, in _call_with_frames_removed
  File "/opt/airflow/dags/dag_main.py", line 6, in <module>
    from functions.class_data_validation import ValidateInputtedData
  File "/opt/airflow/dags/functions/class_data_validation.py", line 6, in <module>
    import great_expectations as ge
ModuleNotFoundError: No module named 'great_expectations'
[2024-05-15T01:29:23.901+0000] {processor.py:842} WARNING - No viable dags retrieved from /opt/airflow/dags/dag_main.py
[2024-05-15T01:29:23.916+0000] {processor.py:183} INFO - Processing /opt/airflow/dags/dag_main.py took 0.285 seconds
[2024-05-15T01:29:54.044+0000] {processor.py:161} INFO - Started process (PID=114) to work on /opt/airflow/dags/dag_main.py
[2024-05-15T01:29:54.046+0000] {processor.py:830} INFO - Processing file /opt/airflow/dags/dag_main.py for tasks to queue
[2024-05-15T01:29:54.048+0000] {logging_mixin.py:188} INFO - [2024-05-15T01:29:54.047+0000] {dagbag.py:540} INFO - Filling up the DagBag from /opt/airflow/dags/dag_main.py
[2024-05-15T01:29:54.445+0000] {logging_mixin.py:188} INFO - [2024-05-15T01:29:54.439+0000] {dagbag.py:350} ERROR - Failed to import: /opt/airflow/dags/dag_main.py
Traceback (most recent call last):
  File "/home/airflow/.local/lib/python3.8/site-packages/airflow/models/dagbag.py", line 346, in parse
    loader.exec_module(new_module)
  File "<frozen importlib._bootstrap_external>", line 843, in exec_module
  File "<frozen importlib._bootstrap>", line 219, in _call_with_frames_removed
  File "/opt/airflow/dags/dag_main.py", line 6, in <module>
    from functions.class_data_validation import ValidateInputtedData
  File "/opt/airflow/dags/functions/class_data_validation.py", line 6, in <module>
    import great_expectations as ge
ModuleNotFoundError: No module named 'great_expectations'
[2024-05-15T01:29:54.447+0000] {processor.py:842} WARNING - No viable dags retrieved from /opt/airflow/dags/dag_main.py
[2024-05-15T01:29:54.462+0000] {processor.py:183} INFO - Processing /opt/airflow/dags/dag_main.py took 0.421 seconds
[2024-05-15T01:32:49.828+0000] {processor.py:161} INFO - Started process (PID=43) to work on /opt/airflow/dags/dag_main.py
[2024-05-15T01:32:49.829+0000] {processor.py:830} INFO - Processing file /opt/airflow/dags/dag_main.py for tasks to queue
[2024-05-15T01:32:49.831+0000] {logging_mixin.py:188} INFO - [2024-05-15T01:32:49.831+0000] {dagbag.py:540} INFO - Filling up the DagBag from /opt/airflow/dags/dag_main.py
[2024-05-15T01:32:51.115+0000] {logging_mixin.py:188} INFO - [2024-05-15T01:32:51.109+0000] {dagbag.py:350} ERROR - Failed to import: /opt/airflow/dags/dag_main.py
Traceback (most recent call last):
  File "/home/airflow/.local/lib/python3.8/site-packages/airflow/models/dagbag.py", line 346, in parse
    loader.exec_module(new_module)
  File "<frozen importlib._bootstrap_external>", line 843, in exec_module
  File "<frozen importlib._bootstrap>", line 219, in _call_with_frames_removed
  File "/opt/airflow/dags/dag_main.py", line 6, in <module>
    from functions.class_data_validation import ValidateInputtedData
  File "/opt/airflow/dags/functions/class_data_validation.py", line 6, in <module>
    import great_expectations as ge
ModuleNotFoundError: No module named 'great_expectations'
[2024-05-15T01:32:51.117+0000] {processor.py:842} WARNING - No viable dags retrieved from /opt/airflow/dags/dag_main.py
[2024-05-15T01:32:51.131+0000] {processor.py:183} INFO - Processing /opt/airflow/dags/dag_main.py took 1.305 seconds
[2024-05-15T01:33:21.957+0000] {processor.py:161} INFO - Started process (PID=54) to work on /opt/airflow/dags/dag_main.py
[2024-05-15T01:33:21.958+0000] {processor.py:830} INFO - Processing file /opt/airflow/dags/dag_main.py for tasks to queue
[2024-05-15T01:33:21.959+0000] {logging_mixin.py:188} INFO - [2024-05-15T01:33:21.959+0000] {dagbag.py:540} INFO - Filling up the DagBag from /opt/airflow/dags/dag_main.py
[2024-05-15T01:33:22.359+0000] {logging_mixin.py:188} INFO - [2024-05-15T01:33:22.353+0000] {dagbag.py:350} ERROR - Failed to import: /opt/airflow/dags/dag_main.py
Traceback (most recent call last):
  File "/home/airflow/.local/lib/python3.8/site-packages/airflow/models/dagbag.py", line 346, in parse
    loader.exec_module(new_module)
  File "<frozen importlib._bootstrap_external>", line 843, in exec_module
  File "<frozen importlib._bootstrap>", line 219, in _call_with_frames_removed
  File "/opt/airflow/dags/dag_main.py", line 6, in <module>
    from functions.class_data_validation import ValidateInputtedData
  File "/opt/airflow/dags/functions/class_data_validation.py", line 6, in <module>
    import great_expectations as ge
ModuleNotFoundError: No module named 'great_expectations'
[2024-05-15T01:33:22.361+0000] {processor.py:842} WARNING - No viable dags retrieved from /opt/airflow/dags/dag_main.py
[2024-05-15T01:33:22.383+0000] {processor.py:183} INFO - Processing /opt/airflow/dags/dag_main.py took 0.430 seconds
[2024-05-15T01:33:53.335+0000] {processor.py:161} INFO - Started process (PID=64) to work on /opt/airflow/dags/dag_main.py
[2024-05-15T01:33:53.336+0000] {processor.py:830} INFO - Processing file /opt/airflow/dags/dag_main.py for tasks to queue
[2024-05-15T01:33:53.337+0000] {logging_mixin.py:188} INFO - [2024-05-15T01:33:53.337+0000] {dagbag.py:540} INFO - Filling up the DagBag from /opt/airflow/dags/dag_main.py
[2024-05-15T01:33:53.724+0000] {logging_mixin.py:188} INFO - [2024-05-15T01:33:53.718+0000] {dagbag.py:350} ERROR - Failed to import: /opt/airflow/dags/dag_main.py
Traceback (most recent call last):
  File "/home/airflow/.local/lib/python3.8/site-packages/airflow/models/dagbag.py", line 346, in parse
    loader.exec_module(new_module)
  File "<frozen importlib._bootstrap_external>", line 843, in exec_module
  File "<frozen importlib._bootstrap>", line 219, in _call_with_frames_removed
  File "/opt/airflow/dags/dag_main.py", line 6, in <module>
    from functions.class_data_validation import ValidateInputtedData
  File "/opt/airflow/dags/functions/class_data_validation.py", line 6, in <module>
    import great_expectations as ge
ModuleNotFoundError: No module named 'great_expectations'
[2024-05-15T01:33:53.726+0000] {processor.py:842} WARNING - No viable dags retrieved from /opt/airflow/dags/dag_main.py
[2024-05-15T01:33:53.743+0000] {processor.py:183} INFO - Processing /opt/airflow/dags/dag_main.py took 0.411 seconds
[2024-05-15T01:34:24.718+0000] {processor.py:161} INFO - Started process (PID=74) to work on /opt/airflow/dags/dag_main.py
[2024-05-15T01:34:24.719+0000] {processor.py:830} INFO - Processing file /opt/airflow/dags/dag_main.py for tasks to queue
[2024-05-15T01:34:24.720+0000] {logging_mixin.py:188} INFO - [2024-05-15T01:34:24.720+0000] {dagbag.py:540} INFO - Filling up the DagBag from /opt/airflow/dags/dag_main.py
[2024-05-15T01:34:25.170+0000] {logging_mixin.py:188} INFO - [2024-05-15T01:34:25.165+0000] {dagbag.py:350} ERROR - Failed to import: /opt/airflow/dags/dag_main.py
Traceback (most recent call last):
  File "/home/airflow/.local/lib/python3.8/site-packages/airflow/models/dagbag.py", line 346, in parse
    loader.exec_module(new_module)
  File "<frozen importlib._bootstrap_external>", line 843, in exec_module
  File "<frozen importlib._bootstrap>", line 219, in _call_with_frames_removed
  File "/opt/airflow/dags/dag_main.py", line 6, in <module>
    from functions.class_data_validation import ValidateInputtedData
  File "/opt/airflow/dags/functions/class_data_validation.py", line 6, in <module>
    import great_expectations as ge
ModuleNotFoundError: No module named 'great_expectations'
[2024-05-15T01:34:25.173+0000] {processor.py:842} WARNING - No viable dags retrieved from /opt/airflow/dags/dag_main.py
[2024-05-15T01:34:25.191+0000] {processor.py:183} INFO - Processing /opt/airflow/dags/dag_main.py took 0.475 seconds
[2024-05-15T01:34:56.131+0000] {processor.py:161} INFO - Started process (PID=84) to work on /opt/airflow/dags/dag_main.py
[2024-05-15T01:34:56.132+0000] {processor.py:830} INFO - Processing file /opt/airflow/dags/dag_main.py for tasks to queue
[2024-05-15T01:34:56.133+0000] {logging_mixin.py:188} INFO - [2024-05-15T01:34:56.133+0000] {dagbag.py:540} INFO - Filling up the DagBag from /opt/airflow/dags/dag_main.py
[2024-05-15T01:34:56.585+0000] {logging_mixin.py:188} INFO - [2024-05-15T01:34:56.578+0000] {dagbag.py:350} ERROR - Failed to import: /opt/airflow/dags/dag_main.py
Traceback (most recent call last):
  File "/home/airflow/.local/lib/python3.8/site-packages/airflow/models/dagbag.py", line 346, in parse
    loader.exec_module(new_module)
  File "<frozen importlib._bootstrap_external>", line 843, in exec_module
  File "<frozen importlib._bootstrap>", line 219, in _call_with_frames_removed
  File "/opt/airflow/dags/dag_main.py", line 6, in <module>
    from functions.class_data_validation import ValidateInputtedData
  File "/opt/airflow/dags/functions/class_data_validation.py", line 6, in <module>
    import great_expectations as ge
ModuleNotFoundError: No module named 'great_expectations'
[2024-05-15T01:34:56.588+0000] {processor.py:842} WARNING - No viable dags retrieved from /opt/airflow/dags/dag_main.py
[2024-05-15T01:34:56.602+0000] {processor.py:183} INFO - Processing /opt/airflow/dags/dag_main.py took 0.474 seconds
[2024-05-15T01:35:27.516+0000] {processor.py:161} INFO - Started process (PID=94) to work on /opt/airflow/dags/dag_main.py
[2024-05-15T01:35:27.517+0000] {processor.py:830} INFO - Processing file /opt/airflow/dags/dag_main.py for tasks to queue
[2024-05-15T01:35:27.518+0000] {logging_mixin.py:188} INFO - [2024-05-15T01:35:27.518+0000] {dagbag.py:540} INFO - Filling up the DagBag from /opt/airflow/dags/dag_main.py
[2024-05-15T01:35:27.818+0000] {logging_mixin.py:188} INFO - [2024-05-15T01:35:27.811+0000] {dagbag.py:350} ERROR - Failed to import: /opt/airflow/dags/dag_main.py
Traceback (most recent call last):
  File "/home/airflow/.local/lib/python3.8/site-packages/airflow/models/dagbag.py", line 346, in parse
    loader.exec_module(new_module)
  File "<frozen importlib._bootstrap_external>", line 843, in exec_module
  File "<frozen importlib._bootstrap>", line 219, in _call_with_frames_removed
  File "/opt/airflow/dags/dag_main.py", line 6, in <module>
    from functions.class_data_validation import ValidateInputtedData
  File "/opt/airflow/dags/functions/class_data_validation.py", line 6, in <module>
    import great_expectations as ge
ModuleNotFoundError: No module named 'great_expectations'
[2024-05-15T01:35:27.820+0000] {processor.py:842} WARNING - No viable dags retrieved from /opt/airflow/dags/dag_main.py
[2024-05-15T01:35:27.842+0000] {processor.py:183} INFO - Processing /opt/airflow/dags/dag_main.py took 0.330 seconds
[2024-05-15T01:35:57.912+0000] {processor.py:161} INFO - Started process (PID=104) to work on /opt/airflow/dags/dag_main.py
[2024-05-15T01:35:57.913+0000] {processor.py:830} INFO - Processing file /opt/airflow/dags/dag_main.py for tasks to queue
[2024-05-15T01:35:57.914+0000] {logging_mixin.py:188} INFO - [2024-05-15T01:35:57.914+0000] {dagbag.py:540} INFO - Filling up the DagBag from /opt/airflow/dags/dag_main.py
[2024-05-15T01:35:58.193+0000] {logging_mixin.py:188} INFO - [2024-05-15T01:35:58.185+0000] {dagbag.py:350} ERROR - Failed to import: /opt/airflow/dags/dag_main.py
Traceback (most recent call last):
  File "/home/airflow/.local/lib/python3.8/site-packages/airflow/models/dagbag.py", line 346, in parse
    loader.exec_module(new_module)
  File "<frozen importlib._bootstrap_external>", line 843, in exec_module
  File "<frozen importlib._bootstrap>", line 219, in _call_with_frames_removed
  File "/opt/airflow/dags/dag_main.py", line 6, in <module>
    from functions.class_data_validation import ValidateInputtedData
  File "/opt/airflow/dags/functions/class_data_validation.py", line 6, in <module>
    import great_expectations as ge
ModuleNotFoundError: No module named 'great_expectations'
[2024-05-15T01:35:58.195+0000] {processor.py:842} WARNING - No viable dags retrieved from /opt/airflow/dags/dag_main.py
[2024-05-15T01:35:58.209+0000] {processor.py:183} INFO - Processing /opt/airflow/dags/dag_main.py took 0.300 seconds
[2024-05-15T01:36:28.311+0000] {processor.py:161} INFO - Started process (PID=114) to work on /opt/airflow/dags/dag_main.py
[2024-05-15T01:36:28.312+0000] {processor.py:830} INFO - Processing file /opt/airflow/dags/dag_main.py for tasks to queue
[2024-05-15T01:36:28.313+0000] {logging_mixin.py:188} INFO - [2024-05-15T01:36:28.312+0000] {dagbag.py:540} INFO - Filling up the DagBag from /opt/airflow/dags/dag_main.py
[2024-05-15T01:36:28.723+0000] {logging_mixin.py:188} INFO - [2024-05-15T01:36:28.719+0000] {dagbag.py:350} ERROR - Failed to import: /opt/airflow/dags/dag_main.py
Traceback (most recent call last):
  File "/home/airflow/.local/lib/python3.8/site-packages/airflow/models/dagbag.py", line 346, in parse
    loader.exec_module(new_module)
  File "<frozen importlib._bootstrap_external>", line 843, in exec_module
  File "<frozen importlib._bootstrap>", line 219, in _call_with_frames_removed
  File "/opt/airflow/dags/dag_main.py", line 6, in <module>
    from functions.class_data_validation import ValidateInputtedData
  File "/opt/airflow/dags/functions/class_data_validation.py", line 6, in <module>
    import great_expectations as ge
ModuleNotFoundError: No module named 'great_expectations'
[2024-05-15T01:36:28.725+0000] {processor.py:842} WARNING - No viable dags retrieved from /opt/airflow/dags/dag_main.py
[2024-05-15T01:36:28.739+0000] {processor.py:183} INFO - Processing /opt/airflow/dags/dag_main.py took 0.432 seconds
[2024-05-15T01:36:59.709+0000] {processor.py:161} INFO - Started process (PID=124) to work on /opt/airflow/dags/dag_main.py
[2024-05-15T01:36:59.710+0000] {processor.py:830} INFO - Processing file /opt/airflow/dags/dag_main.py for tasks to queue
[2024-05-15T01:36:59.711+0000] {logging_mixin.py:188} INFO - [2024-05-15T01:36:59.711+0000] {dagbag.py:540} INFO - Filling up the DagBag from /opt/airflow/dags/dag_main.py
[2024-05-15T01:37:00.158+0000] {logging_mixin.py:188} INFO - [2024-05-15T01:37:00.151+0000] {dagbag.py:350} ERROR - Failed to import: /opt/airflow/dags/dag_main.py
Traceback (most recent call last):
  File "/home/airflow/.local/lib/python3.8/site-packages/airflow/models/dagbag.py", line 346, in parse
    loader.exec_module(new_module)
  File "<frozen importlib._bootstrap_external>", line 843, in exec_module
  File "<frozen importlib._bootstrap>", line 219, in _call_with_frames_removed
  File "/opt/airflow/dags/dag_main.py", line 6, in <module>
    from functions.class_data_validation import ValidateInputtedData
  File "/opt/airflow/dags/functions/class_data_validation.py", line 6, in <module>
    import great_expectations as ge
ModuleNotFoundError: No module named 'great_expectations'
[2024-05-15T01:37:00.160+0000] {processor.py:842} WARNING - No viable dags retrieved from /opt/airflow/dags/dag_main.py
[2024-05-15T01:37:00.176+0000] {processor.py:183} INFO - Processing /opt/airflow/dags/dag_main.py took 0.471 seconds
[2024-05-15T01:37:31.088+0000] {processor.py:161} INFO - Started process (PID=134) to work on /opt/airflow/dags/dag_main.py
[2024-05-15T01:37:31.089+0000] {processor.py:830} INFO - Processing file /opt/airflow/dags/dag_main.py for tasks to queue
[2024-05-15T01:37:31.090+0000] {logging_mixin.py:188} INFO - [2024-05-15T01:37:31.090+0000] {dagbag.py:540} INFO - Filling up the DagBag from /opt/airflow/dags/dag_main.py
[2024-05-15T01:37:31.509+0000] {logging_mixin.py:188} INFO - [2024-05-15T01:37:31.503+0000] {dagbag.py:350} ERROR - Failed to import: /opt/airflow/dags/dag_main.py
Traceback (most recent call last):
  File "/home/airflow/.local/lib/python3.8/site-packages/airflow/models/dagbag.py", line 346, in parse
    loader.exec_module(new_module)
  File "<frozen importlib._bootstrap_external>", line 843, in exec_module
  File "<frozen importlib._bootstrap>", line 219, in _call_with_frames_removed
  File "/opt/airflow/dags/dag_main.py", line 6, in <module>
    from functions.class_data_validation import ValidateInputtedData
  File "/opt/airflow/dags/functions/class_data_validation.py", line 6, in <module>
    import great_expectations as ge
ModuleNotFoundError: No module named 'great_expectations'
[2024-05-15T01:37:31.511+0000] {processor.py:842} WARNING - No viable dags retrieved from /opt/airflow/dags/dag_main.py
[2024-05-15T01:37:31.525+0000] {processor.py:183} INFO - Processing /opt/airflow/dags/dag_main.py took 0.441 seconds
[2024-05-15T01:38:01.582+0000] {processor.py:161} INFO - Started process (PID=145) to work on /opt/airflow/dags/dag_main.py
[2024-05-15T01:38:01.583+0000] {processor.py:830} INFO - Processing file /opt/airflow/dags/dag_main.py for tasks to queue
[2024-05-15T01:38:01.585+0000] {logging_mixin.py:188} INFO - [2024-05-15T01:38:01.584+0000] {dagbag.py:540} INFO - Filling up the DagBag from /opt/airflow/dags/dag_main.py
[2024-05-15T01:38:02.026+0000] {logging_mixin.py:188} INFO - [2024-05-15T01:38:02.020+0000] {dagbag.py:350} ERROR - Failed to import: /opt/airflow/dags/dag_main.py
Traceback (most recent call last):
  File "/home/airflow/.local/lib/python3.8/site-packages/airflow/models/dagbag.py", line 346, in parse
    loader.exec_module(new_module)
  File "<frozen importlib._bootstrap_external>", line 843, in exec_module
  File "<frozen importlib._bootstrap>", line 219, in _call_with_frames_removed
  File "/opt/airflow/dags/dag_main.py", line 6, in <module>
    from functions.class_data_validation import ValidateInputtedData
  File "/opt/airflow/dags/functions/class_data_validation.py", line 6, in <module>
    import great_expectations as ge
ModuleNotFoundError: No module named 'great_expectations'
[2024-05-15T01:38:02.028+0000] {processor.py:842} WARNING - No viable dags retrieved from /opt/airflow/dags/dag_main.py
[2024-05-15T01:38:02.044+0000] {processor.py:183} INFO - Processing /opt/airflow/dags/dag_main.py took 0.465 seconds
[2024-05-15T01:38:32.901+0000] {processor.py:161} INFO - Started process (PID=155) to work on /opt/airflow/dags/dag_main.py
[2024-05-15T01:38:32.902+0000] {processor.py:830} INFO - Processing file /opt/airflow/dags/dag_main.py for tasks to queue
[2024-05-15T01:38:32.903+0000] {logging_mixin.py:188} INFO - [2024-05-15T01:38:32.903+0000] {dagbag.py:540} INFO - Filling up the DagBag from /opt/airflow/dags/dag_main.py
[2024-05-15T01:38:33.177+0000] {logging_mixin.py:188} INFO - [2024-05-15T01:38:33.169+0000] {dagbag.py:350} ERROR - Failed to import: /opt/airflow/dags/dag_main.py
Traceback (most recent call last):
  File "/home/airflow/.local/lib/python3.8/site-packages/airflow/models/dagbag.py", line 346, in parse
    loader.exec_module(new_module)
  File "<frozen importlib._bootstrap_external>", line 843, in exec_module
  File "<frozen importlib._bootstrap>", line 219, in _call_with_frames_removed
  File "/opt/airflow/dags/dag_main.py", line 6, in <module>
    from functions.class_data_validation import ValidateInputtedData
  File "/opt/airflow/dags/functions/class_data_validation.py", line 6, in <module>
    import great_expectations as ge
ModuleNotFoundError: No module named 'great_expectations'
[2024-05-15T01:38:33.178+0000] {processor.py:842} WARNING - No viable dags retrieved from /opt/airflow/dags/dag_main.py
[2024-05-15T01:38:33.196+0000] {processor.py:183} INFO - Processing /opt/airflow/dags/dag_main.py took 0.299 seconds
[2024-05-15T01:39:03.315+0000] {processor.py:161} INFO - Started process (PID=165) to work on /opt/airflow/dags/dag_main.py
[2024-05-15T01:39:03.317+0000] {processor.py:830} INFO - Processing file /opt/airflow/dags/dag_main.py for tasks to queue
[2024-05-15T01:39:03.318+0000] {logging_mixin.py:188} INFO - [2024-05-15T01:39:03.317+0000] {dagbag.py:540} INFO - Filling up the DagBag from /opt/airflow/dags/dag_main.py
[2024-05-15T01:39:03.575+0000] {logging_mixin.py:188} INFO - [2024-05-15T01:39:03.564+0000] {dagbag.py:350} ERROR - Failed to import: /opt/airflow/dags/dag_main.py
Traceback (most recent call last):
  File "/home/airflow/.local/lib/python3.8/site-packages/airflow/models/dagbag.py", line 346, in parse
    loader.exec_module(new_module)
  File "<frozen importlib._bootstrap_external>", line 843, in exec_module
  File "<frozen importlib._bootstrap>", line 219, in _call_with_frames_removed
  File "/opt/airflow/dags/dag_main.py", line 6, in <module>
    from functions.class_data_validation import ValidateInputtedData
  File "/opt/airflow/dags/functions/class_data_validation.py", line 6, in <module>
    import great_expectations as ge
ModuleNotFoundError: No module named 'great_expectations'
[2024-05-15T01:39:03.578+0000] {processor.py:842} WARNING - No viable dags retrieved from /opt/airflow/dags/dag_main.py
[2024-05-15T01:39:03.591+0000] {processor.py:183} INFO - Processing /opt/airflow/dags/dag_main.py took 0.279 seconds
[2024-05-15T01:39:33.723+0000] {processor.py:161} INFO - Started process (PID=175) to work on /opt/airflow/dags/dag_main.py
[2024-05-15T01:39:33.725+0000] {processor.py:830} INFO - Processing file /opt/airflow/dags/dag_main.py for tasks to queue
[2024-05-15T01:39:33.726+0000] {logging_mixin.py:188} INFO - [2024-05-15T01:39:33.726+0000] {dagbag.py:540} INFO - Filling up the DagBag from /opt/airflow/dags/dag_main.py
[2024-05-15T01:39:34.236+0000] {logging_mixin.py:188} INFO - [2024-05-15T01:39:34.231+0000] {dagbag.py:350} ERROR - Failed to import: /opt/airflow/dags/dag_main.py
Traceback (most recent call last):
  File "/home/airflow/.local/lib/python3.8/site-packages/airflow/models/dagbag.py", line 346, in parse
    loader.exec_module(new_module)
  File "<frozen importlib._bootstrap_external>", line 843, in exec_module
  File "<frozen importlib._bootstrap>", line 219, in _call_with_frames_removed
  File "/opt/airflow/dags/dag_main.py", line 6, in <module>
    from functions.class_data_validation import ValidateInputtedData
  File "/opt/airflow/dags/functions/class_data_validation.py", line 6, in <module>
    import great_expectations as ge
ModuleNotFoundError: No module named 'great_expectations'
[2024-05-15T01:39:34.238+0000] {processor.py:842} WARNING - No viable dags retrieved from /opt/airflow/dags/dag_main.py
[2024-05-15T01:39:34.251+0000] {processor.py:183} INFO - Processing /opt/airflow/dags/dag_main.py took 0.532 seconds
